Workbook

Sheet Instructions
A1: FIFA WORLD CUP 2026 SWEEPSTAKE
A3: HOW TO USE THIS WORKBOOK
A5: STEP 1: Collect Participants
A6: - Send out your Microsoft Form for registration
A7: - Paste participant names into the 'Participants' sheet column B
A8: - Have them nominate a Golden Boot player in column C
A10: STEP 2: Allocate Teams
A11: - Save this file as .xlsm (macro-enabled workbook)
A12: - Import the VBA macro from 'allocation_macro.bas' (Alt+F11 > Import)
A13: - Run the macro 'AllocateTeams' (Alt+F8 > AllocateTeams > Run)
A14: - Teams are randomly assigned in cycles of 48
A15: - First 48 participants each get a unique team
... A67: Teams can be shared across cycles (e.g., 2 people may have Brazil).

Sheet Teams
A1: FIFA World Cup 2026 - All 48 Teams
A3: # | B3: Team | C3: Group
A4: 1 | B4: Mexico | C4: Group A
A5: 2 | B5: South Africa | C5: Group A
A6: 3 | B6: South Korea | C6: Group A
A7: 4 | B7: Czechia | C7: Group A
A8: 5 | B8: Canada | C8: Group B
A9: 6 | B9: Bosnia and Herzegovina | C9: Group B
A10: 7 | B10: Qatar | C10: Group B
A11: 8 | B11: Switzerland | C11: Group B
A12: 9 | B12: Brazil | C12: Group C
A13: 10 | B13: Morocco | C13: Group C
A14: 11 | B14: Haiti | C14: Group C
A15: 12 | B15: Scotland | C15: Group C
... A51: 48 | B51: Panama | C51: Group L

Sheet Participants
A1: Participant Registration
A2: Paste names from Microsoft Forms below. One name per row.
A4: # | B4: Participant Name | C4: Golden Boot Nomination
A5: 1 | B5: James Wilson | C5: Kylian Mbappé
A6: 2 | B6: Sarah Chen | C6: Lionel Messi
A7: 3 | B7: Michael O'Brien | C7: Erling Haaland
A8: 4 | B8: Emma Thompson | C8: Vinícius Júnior
A9: 5 | B9: David Kumar | C9: Harry Kane
A10: 6 | B10: Rachel Stewart | C10: Mohamed Salah
A11: 7 | B11: Chris Martinez | C11: Jude Bellingham
A12: 8 | B12: Jessica Park | C12: Lamine Yamal
A13: 9 | B13: Andrew Collins | C13: Bukayo Saka
A14: 10 | B14: Laura Bennett | C14: Victor Osimhen
A15: 11 | B15: Tom Nguyen | C15: Cristiano Ronaldo
A16: 12 | B16: Sophie Williams | C16: Robert Lewandowski
... A54: 50 | B54: Sienna Cole | C54: Donyell Malen
A55: 51
A56: 52
A57: 53
A58: 54
A59: 55
A60: 56
A61: 57
A62: 58
A63: 59
A64: 60
A65: 61
A66: 62
... A104: 100

Sheet Allocation
A1: Team Allocation
A2: Run the 'AllocateTeams' macro to randomly assign teams to participants.
A3: Teams are allocated in cycles of 48 - all 48 teams used before repeating.
A5: # | B5: Participant Name | C5: Allocated Team | D5: Group | E5: Cycle

Sheet Fixtures
A1: FIFA World Cup 2026 - Match Results
A2: Enter scores in columns E and F. Points calculate automatically.
A4: Match | B4: Date | C4: Stage | D4: Home Team | E4: Home Score | F4: Away Score | G4: Away Team | H4: Home Pts | I4: Away Pts | J4: Home Result | K4: Away Result
A5: 1 | B5: 11-Jun | C5: A | D5: Mexico | G5: South Africa | H5: =IF(AND(E5<>"",F5<>""),IF(E5>F5,3,IF(E5=F5,1,0)),"") | I5: =IF(AND(E5<>"",F5<>""),IF(F5>E5,3,IF(E5=F5,1,0)),"") | J5: =IF(AND(E5<>"",F5<>""),IF(E5>F5,"W",IF(E5=F5,"D","L")),"") | K5: =IF(AND(E5<>"",F5<>""),IF(F5>E5,"W",IF(E5=F5,"D","L")),"")
A6: 2 | B6: 11-Jun | C6: A | D6: South Korea | G6: Czechia | H6: =IF(AND(E6<>"",F6<>""),IF(E6>F6,3,IF(E6=F6,1,0)),"") | I6: =IF(AND(E6<>"",F6<>""),IF(F6>E6,3,IF(E6=F6,1,0)),"") | J6: =IF(AND(E6<>"",F6<>""),IF(E6>F6,"W",IF(E6=F6,"D","L")),"") | K6: =IF(AND(E6<>"",F6<>""),IF(F6>E6,"W",IF(E6=F6,"D","L")),"")
A7: 3 | B7: 12-Jun | C7: B | D7: Canada | G7: Bosnia and Herzegovina | H7: =IF(AND(E7<>"",F7<>""),IF(E7>F7,3,IF(E7=F7,1,0)),"") | I7: =IF(AND(E7<>"",F7<>""),IF(F7>E7,3,IF(E7=F7,1,0)),"") | J7: =IF(AND(E7<>"",F7<>""),IF(E7>F7,"W",IF(E7=F7,"D","L")),"") | K7: =IF(AND(E7<>"",F7<>""),IF(F7>E7,"W",IF(E7=F7,"D","L")),"")
A8: 4 | B8: 12-Jun | C8: D | D8: United States | G8: Paraguay | H8: =IF(AND(E8<>"",F8<>""),IF(E8>F8,3,IF(E8=F8,1,0)),"") | I8: =IF(AND(E8<>"",F8<>""),IF(F8>E8,3,IF(E8=F8,1,0)),"") | J8: =IF(AND(E8<>"",F8<>""),IF(E8>F8,"W",IF(E8=F8,"D","L")),"") | K8: =IF(AND(E8<>"",F8<>""),IF(F8>E8,"W",IF(E8=F8,"D","L")),"")
A9: 5 | B9: 13-Jun | C9: C | D9: Haiti | G9: Scotland | H9: =IF(AND(E9<>"",F9<>""),IF(E9>F9,3,IF(E9=F9,1,0)),"") | I9: =IF(AND(E9<>"",F9<>""),IF(F9>E9,3,IF(E9=F9,1,0)),"") | J9: =IF(AND(E9<>"",F9<>""),IF(E9>F9,"W",IF(E9=F9,"D","L")),"") | K9: =IF(AND(E9<>"",F9<>""),IF(F9>E9,"W",IF(E9=F9,"D","L")),"")
A10: 6 | B10: 13-Jun | C10: D | D10: Australia | G10: Türkiye | H10: =IF(AND(E10<>"",F10<>""),IF(E10>F10,3,IF(E10=F10,1,0)),"") | I10: =IF(AND(E10<>"",F10<>""),IF(F10>E10,3,IF(E10=F10,1,0)),"") | J10: =IF(AND(E10<>"",F10<>""),IF(E10>F10,"W",IF(E10=F10,"D","L")),"") | K10: =IF(AND(E10<>"",F10<>""),IF(F10>E10,"W",IF(E10=F10,"D","L")),"")
A11: 7 | B11: 13-Jun | C11: C | D11: Brazil | G11: Morocco | H11: =IF(AND(E11<>"",F11<>""),IF(E11>F11,3,IF(E11=F11,1,0)),"") | I11: =IF(AND(E11<>"",F11<>""),IF(F11>E11,3,IF(E11=F11,1,0)),"") | J11: =IF(AND(E11<>"",F11<>""),IF(E11>F11,"W",IF(E11=F11,"D","L")),"") | K11: =IF(AND(E11<>"",F11<>""),IF(F11>E11,"W",IF(E11=F11,"D","L")),"")
A12: 8 | B12: 13-Jun | C12: B | D12: Qatar | G12: Switzerland | H12: =IF(AND(E12<>"",F12<>""),IF(E12>F12,3,IF(E12=F12,1,0)),"") | I12: =IF(AND(E12<>"",F12<>""),IF(F12>E12,3,IF(E12=F12,1,0)),"") | J12: =IF(AND(E12<>"",F12<>""),IF(E12>F12,"W",IF(E12=F12,"D","L")),"") | K12: =IF(AND(E12<>"",F12<>""),IF(F12>E12,"W",IF(E12=F12,"D","L")),"")
A13: 9 | B13: 14-Jun | C13: E | D13: Ivory Coast | G13: Ecuador | H13: =IF(AND(E13<>"",F13<>""),IF(E13>F13,3,IF(E13=F13,1,0)),"") | I13: =IF(AND(E13<>"",F13<>""),IF(F13>E13,3,IF(E13=F13,1,0)),"") | J13: =IF(AND(E13<>"",F13<>""),IF(E13>F13,"W",IF(E13=F13,"D","L")),"") | K13: =IF(AND(E13<>"",F13<>""),IF(F13>E13,"W",IF(E13=F13,"D","L")),"")
A14: 10 | B14: 14-Jun | C14: E | D14: Germany | G14: Curaçao | H14: =IF(AND(E14<>"",F14<>""),IF(E14>F14,3,IF(E14=F14,1,0)),"") | I14: =IF(AND(E14<>"",F14<>""),IF(F14>E14,3,IF(E14=F14,1,0)),"") | J14: =IF(AND(E14<>"",F14<>""),IF(E14>F14,"W",IF(E14=F14,"D","L")),"") | K14: =IF(AND(E14<>"",F14<>""),IF(F14>E14,"W",IF(E14=F14,"D","L")),"")
A15: 11 | B15: 14-Jun | C15: F | D15: Netherlands | G15: Japan | H15: =IF(AND(E15<>"",F15<>""),IF(E15>F15,3,IF(E15=F15,1,0)),"") | I15: =IF(AND(E15<>"",F15<>""),IF(F15>E15,3,IF(E15=F15,1,0)),"") | J15: =IF(AND(E15<>"",F15<>""),IF(E15>F15,"W",IF(E15=F15,"D","L")),"") | K15: =IF(AND(E15<>"",F15<>""),IF(F15>E15,"W",IF(E15=F15,"D","L")),"")
A16: 12 | B16: 14-Jun | C16: F | D16: Sweden | G16: Tunisia | H16: =IF(AND(E16<>"",F16<>""),IF(E16>F16,3,IF(E16=F16,1,0)),"") | I16: =IF(AND(E16<>"",F16<>""),IF(F16>E16,3,IF(E16=F16,1,0)),"") | J16: =IF(AND(E16<>"",F16<>""),IF(E16>F16,"W",IF(E16=F16,"D","L")),"") | K16: =IF(AND(E16<>"",F16<>""),IF(F16>E16,"W",IF(E16=F16,"D","L")),"")
... A108: 104 | B108: 19-Jul | C108: Final | D108: W101 | G108: W102 | H108: =IF(AND(E108<>"",F108<>""),IF(E108>F108,3,IF(E108=F108,1,0)),"") | I108: =IF(AND(E108<>"",F108<>""),IF(F108>E108,3,IF(E108=F108,1,0)),"") | J108: =IF(AND(E108<>"",F108<>""),IF(E108>F108,"W",IF(E108=F108,"D","L")),"") | K108: =IF(AND(E108<>"",F108<>""),IF(F108>E108,"W",IF(E108=F108,"D","L")),"")

Sheet Points
A1: Team Points Summary
A2: Auto-calculated from Fixtures sheet results.
A4: # | B4: Team | C4: Group | D4: Played | E4: Won | F4: Drawn | G4: Lost | H4: GF | I4: GA | J4: GD | K4: Points
A5: 1 | B5: Mexico | C5: Group A | D5: =COUNTIFS(Fixtures!D$5:D$76,B5,Fixtures!E$5:E$76,"<>")+COUNTIFS(Fixtures!G$5:G$76,B5,Fixtures!F$5:F$76,"<>") | E5: =COUNTIFS(Fixtures!D$5:D$76,B5,Fixtures!J$5:J$76,"W")+COUNTIFS(Fixtures!G$5:G$76,B5,Fixtures!K$5:K$76,"W") | F5: =COUNTIFS(Fixtures!D$5:D$76,B5,Fixtures!J$5:J$76,"D")+COUNTIFS(Fixtures!G$5:G$76,B5,Fixtures!K$5:K$76,"D") | G5: =COUNTIFS(Fixtures!D$5:D$76,B5,Fixtures!J$5:J$76,"L")+COUNTIFS(Fixtures!G$5:G$76,B5,Fixtures!K$5:K$76,"L") | H5: =SUMPRODUCT((Fixtures!D$5:D$76=B5)*(Fixtures!E$5:E$76<>"")*Fixtures!E$5:E$76)+SUMPRODUCT((Fixtures!G$5:G$76=B5)*(Fixtures!F$5:F$76<>"")*Fixtures!F$5:F$76) | I5: =SUMPRODUCT((Fixtures!D$5:D$76=B5)*(Fixtures!F$5:F$76<>"")*Fixtures!F$5:F$76)+SUMPRODUCT((Fixtures!G$5:G$76=B5)*(Fixtures!E$5:E$76<>"")*Fixtures!E$5:E$76) | J5: =H5-I5 | K5: =SUMPRODUCT((Fixtures!D$5:D$76=B5)*(Fixtures!E$5:E$76<>"")*(Fixtures!F$5:F$76<>"")*((Fixtures!E$5:E$76>Fixtures!F$5:F$76)*3+(Fixtures!E$5:E$76=Fixtures!F$5:F$76)*2))+SUMPRODUCT((Fixtures!G$5:G$76=B5)*(Fixtures!E$5:E$76<>"")*(Fixtures!F$5:F$76<>"")*((Fixtures!F$5:F$76>Fixtures!E$5:E$76)*3+(Fixtures!E$5:E$76=Fixtures!F$5:F$76)*2))
A6: 2 | B6: South Africa | C6: Group A | D6: =COUNTIFS(Fixtures!D$5:D$76,B6,Fixtures!E$5:E$76,"<>")+COUNTIFS(Fixtures!G$5:G$76,B6,Fixtures!F$5:F$76,"<>") | E6: =COUNTIFS(Fixtures!D$5:D$76,B6,Fixtures!J$5:J$76,"W")+COUNTIFS(Fixtures!G$5:G$76,B6,Fixtures!K$5:K$76,"W") | F6: =COUNTIFS(Fixtures!D$5:D$76,B6,Fixtures!J$5:J$76,"D")+COUNTIFS(Fixtures!G$5:G$76,B6,Fixtures!K$5:K$76,"D") | G6: =COUNTIFS(Fixtures!D$5:D$76,B6,Fixtures!J$5:J$76,"L")+COUNTIFS(Fixtures!G$5:G$76,B6,Fixtures!K$5:K$76,"L") | H6: =SUMPRODUCT((Fixtures!D$5:D$76=B6)*(Fixtures!E$5:E$76<>"")*Fixtures!E$5:E$76)+SUMPRODUCT((Fixtures!G$5:G$76=B6)*(Fixtures!F$5:F$76<>"")*Fixtures!F$5:F$76) | I6: =SUMPRODUCT((Fixtures!D$5:D$76=B6)*(Fixtures!F$5:F$76<>"")*Fixtures!F$5:F$76)+SUMPRODUCT((Fixtures!G$5:G$76=B6)*(Fixtures!E$5:E$76<>"")*Fixtures!E$5:E$76) | J6: =H6-I6 | K6: =SUMPRODUCT((Fixtures!D$5:D$76=B6)*(Fixtures!E$5:E$76<>"")*(Fixtures!F$5:F$76<>"")*((Fixtures!E$5:E$76>Fixtures!F$5:F$76)*3+(Fixtures!E$5:E$76=Fixtures!F$5:F$76)*2))+SUMPRODUCT((Fixtures!G$5:G$76=B6)*(Fixtures!E$5:E$76<>"")*(Fixtures!F$5:F$76<>"")*((Fixtures!F$5:F$76>Fixtures!E$5:E$76)*3+(Fixtures!E$5:E$76=Fixtures!F$5:F$76)*2))
A7: 3 | B7: South Korea | C7: Group A | D7: =COUNTIFS(Fixtures!D$5:D$76,B7,Fixtures!E$5:E$76,"<>")+COUNTIFS(Fixtures!G$5:G$76,B7,Fixtures!F$5:F$76,"<>") | E7: =COUNTIFS(Fixtures!D$5:D$76,B7,Fixtures!J$5:J$76,"W")+COUNTIFS(Fixtures!G$5:G$76,B7,Fixtures!K$5:K$76,"W") | F7: =COUNTIFS(Fixtures!D$5:D$76,B7,Fixtures!J$5:J$76,"D")+COUNTIFS(Fixtures!G$5:G$76,B7,Fixtures!K$5:K$76,"D") | G7: =COUNTIFS(Fixtures!D$5:D$76,B7,Fixtures!J$5:J$76,"L")+COUNTIFS(Fixtures!G$5:G$76,B7,Fixtures!K$5:K$76,"L") | H7: =SUMPRODUCT((Fixtures!D$5:D$76=B7)*(Fixtures!E$5:E$76<>"")*Fixtures!E$5:E$76)+SUMPRODUCT((Fixtures!G$5:G$76=B7)*(Fixtures!F$5:F$76<>"")*Fixtures!F$5:F$76) | I7: =SUMPRODUCT((Fixtures!D$5:D$76=B7)*(Fixtures!F$5:F$76<>"")*Fixtures!F$5:F$76)+SUMPRODUCT((Fixtures!G$5:G$76=B7)*(Fixtures!E$5:E$76<>"")*Fixtures!E$5:E$76) | J7: =H7-I7 | K7: =SUMPRODUCT((Fixtures!D$5:D$76=B7)*(Fixtures!E$5:E$76<>"")*(Fixtures!F$5:F$76<>"")*((Fixtures!E$5:E$76>Fixtures!F$5:F$76)*3+(Fixtures!E$5:E$76=Fixtures!F$5:F$76)*2))+SUMPRODUCT((Fixtures!G$5:G$76=B7)*(Fixtures!E$5:E$76<>"")*(Fixtures!F$5:F$76<>"")*((Fixtures!F$5:F$76>Fixtures!E$5:E$76)*3+(Fixtures!E$5:E$76=Fixtures!F$5:F$76)*2))
A8: 4 | B8: Czechia | C8: Group A | D8: =COUNTIFS(Fixtures!D$5:D$76,B8,Fixtures!E$5:E$76,"<>")+COUNTIFS(Fixtures!G$5:G$76,B8,Fixtures!F$5:F$76,"<>") | E8: =COUNTIFS(Fixtures!D$5:D$76,B8,Fixtures!J$5:J$76,"W")+COUNTIFS(Fixtures!G$5:G$76,B8,Fixtures!K$5:K$76,"W") | F8: =COUNTIFS(Fixtures!D$5:D$76,B8,Fixtures!J$5:J$76,"D")+COUNTIFS(Fixtures!G$5:G$76,B8,Fixtures!K$5:K$76,"D") | G8: =COUNTIFS(Fixtures!D$5:D$76,B8,Fixtures!J$5:J$76,"L")+COUNTIFS(Fixtures!G$5:G$76,B8,Fixtures!K$5:K$76,"L") | H8: =SUMPRODUCT((Fixtures!D$5:D$76=B8)*(Fixtures!E$5:E$76<>"")*Fixtures!E$5:E$76)+SUMPRODUCT((Fixtures!G$5:G$76=B8)*(Fixtures!F$5:F$76<>"")*Fixtures!F$5:F$76) | I8: =SUMPRODUCT((Fixtures!D$5:D$76=B8)*(Fixtures!F$5:F$76<>"")*Fixtures!F$5:F$76)+SUMPRODUCT((Fixtures!G$5:G$76=B8)*(Fixtures!E$5:E$76<>"")*Fixtures!E$5:E$76) | J8: =H8-I8 | K8: =SUMPRODUCT((Fixtures!D$5:D$76=B8)*(Fixtures!E$5:E$76<>"")*(Fixtures!F$5:F$76<>"")*((Fixtures!E$5:E$76>Fixtures!F$5:F$76)*3+(Fixtures!E$5:E$76=Fixtures!F$5:F$76)*2))+SUMPRODUCT((Fixtures!G$5:G$76=B8)*(Fixtures!E$5:E$76<>"")*(Fixtures!F$5:F$76<>"")*((Fixtures!F$5:F$76>Fixtures!E$5:E$76)*3+(Fixtures!E$5:E$76=Fixtures!F$5:F$76)*2))
A9: 5 | B9: Canada | C9: Group B | D9: =COUNTIFS(Fixtures!D$5:D$76,B9,Fixtures!E$5:E$76,"<>")+COUNTIFS(Fixtures!G$5:G$76,B9,Fixtures!F$5:F$76,"<>") | E9: =COUNTIFS(Fixtures!D$5:D$76,B9,Fixtures!J$5:J$76,"W")+COUNTIFS(Fixtures!G$5:G$76,B9,Fixtures!K$5:K$76,"W") | F9: =COUNTIFS(Fixtures!D$5:D$76,B9,Fixtures!J$5:J$76,"D")+COUNTIFS(Fixtures!G$5:G$76,B9,Fixtures!K$5:K$76,"D") | G9: =COUNTIFS(Fixtures!D$5:D$76,B9,Fixtures!J$5:J$76,"L")+COUNTIFS(Fixtures!G$5:G$76,B9,Fixtures!K$5:K$76,"L") | H9: =SUMPRODUCT((Fixtures!D$5:D$76=B9)*(Fixtures!E$5:E$76<>"")*Fixtures!E$5:E$76)+SUMPRODUCT((Fixtures!G$5:G$76=B9)*(Fixtures!F$5:F$76<>"")*Fixtures!F$5:F$76) | I9: =SUMPRODUCT((Fixtures!D$5:D$76=B9)*(Fixtures!F$5:F$76<>"")*Fixtures!F$5:F$76)+SUMPRODUCT((Fixtures!G$5:G$76=B9)*(Fixtures!E$5:E$76<>"")*Fixtures!E$5:E$76) | J9: =H9-I9 | K9: =SUMPRODUCT((Fixtures!D$5:D$76=B9)*(Fixtures!E$5:E$76<>"")*(Fixtures!F$5:F$76<>"")*((Fixtures!E$5:E$76>Fixtures!F$5:F$76)*3+(Fixtures!E$5:E$76=Fixtures!F$5:F$76)*2))+SUMPRODUCT((Fixtures!G$5:G$76=B9)*(Fixtures!E$5:E$76<>"")*(Fixtures!F$5:F$76<>"")*((Fixtures!F$5:F$76>Fixtures!E$5:E$76)*3+(Fixtures!E$5:E$76=Fixtures!F$5:F$76)*2))
A10: 6 | B10: Bosnia and Herzegovina | C10: Group B | D10: =COUNTIFS(Fixtures!D$5:D$76,B10,Fixtures!E$5:E$76,"<>")+COUNTIFS(Fixtures!G$5:G$76,B10,Fixtures!F$5:F$76,"<>") | E10: =COUNTIFS(Fixtures!D$5:D$76,B10,Fixtures!J$5:J$76,"W")+COUNTIFS(Fixtures!G$5:G$76,B10,Fixtures!K$5:K$76,"W") | F10: =COUNTIFS(Fixtures!D$5:D$76,B10,Fixtures!J$5:J$76,"D")+COUNTIFS(Fixtures!G$5:G$76,B10,Fixtures!K$5:K$76,"D") | G10: =COUNTIFS(Fixtures!D$5:D$76,B10,Fixtures!J$5:J$76,"L")+COUNTIFS(Fixtures!G$5:G$76,B10,Fixtures!K$5:K$76,"L") | H10: =SUMPRODUCT((Fixtures!D$5:D$76=B10)*(Fixtures!E$5:E$76<>"")*Fixtures!E$5:E$76)+SUMPRODUCT((Fixtures!G$5:G$76=B10)*(Fixtures!F$5:F$76<>"")*Fixtures!F$5:F$76) | I10: =SUMPRODUCT((Fixtures!D$5:D$76=B10)*(Fixtures!F$5:F$76<>"")*Fixtures!F$5:F$76)+SUMPRODUCT((Fixtures!G$5:G$76=B10)*(Fixtures!E$5:E$76<>"")*Fixtures!E$5:E$76) | J10: =H10-I10 | K10: =SUMPRODUCT((Fixtures!D$5:D$76=B10)*(Fixtures!E$5:E$76<>"")*(Fixtures!F$5:F$76<>"")*((Fixtures!E$5:E$76>Fixtures!F$5:F$76)*3+(Fixtures!E$5:E$76=Fixtures!F$5:F$76)*2))+SUMPRODUCT((Fixtures!G$5:G$76=B10)*(Fixtures!E$5:E$76<>"")*(Fixtures!F$5:F$76<>"")*((Fixtures!F$5:F$76>Fixtures!E$5:E$76)*3+(Fixtures!E$5:E$76=Fixtures!F$5:F$76)*2))
A11: 7 | B11: Qatar | C11: Group B | D11: =COUNTIFS(Fixtures!D$5:D$76,B11,Fixtures!E$5:E$76,"<>")+COUNTIFS(Fixtures!G$5:G$76,B11,Fixtures!F$5:F$76,"<>") | E11: =COUNTIFS(Fixtures!D$5:D$76,B11,Fixtures!J$5:J$76,"W")+COUNTIFS(Fixtures!G$5:G$76,B11,Fixtures!K$5:K$76,"W") | F11: =COUNTIFS(Fixtures!D$5:D$76,B11,Fixtures!J$5:J$76,"D")+COUNTIFS(Fixtures!G$5:G$76,B11,Fixtures!K$5:K$76,"D") | G11: =COUNTIFS(Fixtures!D$5:D$76,B11,Fixtures!J$5:J$76,"L")+COUNTIFS(Fixtures!G$5:G$76,B11,Fixtures!K$5:K$76,"L") | H11: =SUMPRODUCT((Fixtures!D$5:D$76=B11)*(Fixtures!E$5:E$76<>"")*Fixtures!E$5:E$76)+SUMPRODUCT((Fixtures!G$5:G$76=B11)*(Fixtures!F$5:F$76<>"")*Fixtures!F$5:F$76) | I11: =SUMPRODUCT((Fixtures!D$5:D$76=B11)*(Fixtures!F$5:F$76<>"")*Fixtures!F$5:F$76)+SUMPRODUCT((Fixtures!G$5:G$76=B11)*(Fixtures!E$5:E$76<>"")*Fixtures!E$5:E$76) | J11: =H11-I11 | K11: =SUMPRODUCT((Fixtures!D$5:D$76=B11)*(Fixtures!E$5:E$76<>"")*(Fixtures!F$5:F$76<>"")*((Fixtures!E$5:E$76>Fixtures!F$5:F$76)*3+(Fixtures!E$5:E$76=Fixtures!F$5:F$76)*2))+SUMPRODUCT((Fixtures!G$5:G$76=B11)*(Fixtures!E$5:E$76<>"")*(Fixtures!F$5:F$76<>"")*((Fixtures!F$5:F$76>Fixtures!E$5:E$76)*3+(Fixtures!E$5:E$76=Fixtures!F$5:F$76)*2))
A12: 8 | B12: Switzerland | C12: Group B | D12: =COUNTIFS(Fixtures!D$5:D$76,B12,Fixtures!E$5:E$76,"<>")+COUNTIFS(Fixtures!G$5:G$76,B12,Fixtures!F$5:F$76,"<>") | E12: =COUNTIFS(Fixtures!D$5:D$76,B12,Fixtures!J$5:J$76,"W")+COUNTIFS(Fixtures!G$5:G$76,B12,Fixtures!K$5:K$76,"W") | F12: =COUNTIFS(Fixtures!D$5:D$76,B12,Fixtures!J$5:J$76,"D")+COUNTIFS(Fixtures!G$5:G$76,B12,Fixtures!K$5:K$76,"D") | G12: =COUNTIFS(Fixtures!D$5:D$76,B12,Fixtures!J$5:J$76,"L")+COUNTIFS(Fixtures!G$5:G$76,B12,Fixtures!K$5:K$76,"L") | H12: =SUMPRODUCT((Fixtures!D$5:D$76=B12)*(Fixtures!E$5:E$76<>"")*Fixtures!E$5:E$76)+SUMPRODUCT((Fixtures!G$5:G$76=B12)*(Fixtures!F$5:F$76<>"")*Fixtures!F$5:F$76) | I12: =SUMPRODUCT((Fixtures!D$5:D$76=B12)*(Fixtures!F$5:F$76<>"")*Fixtures!F$5:F$76)+SUMPRODUCT((Fixtures!G$5:G$76=B12)*(Fixtures!E$5:E$76<>"")*Fixtures!E$5:E$76) | J12: =H12-I12 | K12: =SUMPRODUCT((Fixtures!D$5:D$76=B12)*(Fixtures!E$5:E$76<>"")*(Fixtures!F$5:F$76<>"")*((Fixtures!E$5:E$76>Fixtures!F$5:F$76)*3+(Fixtures!E$5:E$76=Fixtures!F$5:F$76)*2))+SUMPRODUCT((Fixtures!G$5:G$76=B12)*(Fixtures!E$5:E$76<>"")*(Fixtures!F$5:F$76<>"")*((Fixtures!F$5:F$76>Fixtures!E$5:E$76)*3+(Fixtures!E$5:E$76=Fixtures!F$5:F$76)*2))
A13: 9 | B13: Brazil | C13: Group C | D13: =COUNTIFS(Fixtures!D$5:D$76,B13,Fixtures!E$5:E$76,"<>")+COUNTIFS(Fixtures!G$5:G$76,B13,Fixtures!F$5:F$76,"<>") | E13: =COUNTIFS(Fixtures!D$5:D$76,B13,Fixtures!J$5:J$76,"W")+COUNTIFS(Fixtures!G$5:G$76,B13,Fixtures!K$5:K$76,"W") | F13: =COUNTIFS(Fixtures!D$5:D$76,B13,Fixtures!J$5:J$76,"D")+COUNTIFS(Fixtures!G$5:G$76,B13,Fixtures!K$5:K$76,"D") | G13: =COUNTIFS(Fixtures!D$5:D$76,B13,Fixtures!J$5:J$76,"L")+COUNTIFS(Fixtures!G$5:G$76,B13,Fixtures!K$5:K$76,"L") | H13: =SUMPRODUCT((Fixtures!D$5:D$76=B13)*(Fixtures!E$5:E$76<>"")*Fixtures!E$5:E$76)+SUMPRODUCT((Fixtures!G$5:G$76=B13)*(Fixtures!F$5:F$76<>"")*Fixtures!F$5:F$76) | I13: =SUMPRODUCT((Fixtures!D$5:D$76=B13)*(Fixtures!F$5:F$76<>"")*Fixtures!F$5:F$76)+SUMPRODUCT((Fixtures!G$5:G$76=B13)*(Fixtures!E$5:E$76<>"")*Fixtures!E$5:E$76) | J13: =H13-I13 | K13: =SUMPRODUCT((Fixtures!D$5:D$76=B13)*(Fixtures!E$5:E$76<>"")*(Fixtures!F$5:F$76<>"")*((Fixtures!E$5:E$76>Fixtures!F$5:F$76)*3+(Fixtures!E$5:E$76=Fixtures!F$5:F$76)*2))+SUMPRODUCT((Fixtures!G$5:G$76=B13)*(Fixtures!E$5:E$76<>"")*(Fixtures!F$5:F$76<>"")*((Fixtures!F$5:F$76>Fixtures!E$5:E$76)*3+(Fixtures!E$5:E$76=Fixtures!F$5:F$76)*2))
A14: 10 | B14: Morocco | C14: Group C | D14: =COUNTIFS(Fixtures!D$5:D$76,B14,Fixtures!E$5:E$76,"<>")+COUNTIFS(Fixtures!G$5:G$76,B14,Fixtures!F$5:F$76,"<>") | E14: =COUNTIFS(Fixtures!D$5:D$76,B14,Fixtures!J$5:J$76,"W")+COUNTIFS(Fixtures!G$5:G$76,B14,Fixtures!K$5:K$76,"W") | F14: =COUNTIFS(Fixtures!D$5:D$76,B14,Fixtures!J$5:J$76,"D")+COUNTIFS(Fixtures!G$5:G$76,B14,Fixtures!K$5:K$76,"D") | G14: =COUNTIFS(Fixtures!D$5:D$76,B14,Fixtures!J$5:J$76,"L")+COUNTIFS(Fixtures!G$5:G$76,B14,Fixtures!K$5:K$76,"L") | H14: =SUMPRODUCT((Fixtures!D$5:D$76=B14)*(Fixtures!E$5:E$76<>"")*Fixtures!E$5:E$76)+SUMPRODUCT((Fixtures!G$5:G$76=B14)*(Fixtures!F$5:F$76<>"")*Fixtures!F$5:F$76) | I14: =SUMPRODUCT((Fixtures!D$5:D$76=B14)*(Fixtures!F$5:F$76<>"")*Fixtures!F$5:F$76)+SUMPRODUCT((Fixtures!G$5:G$76=B14)*(Fixtures!E$5:E$76<>"")*Fixtures!E$5:E$76) | J14: =H14-I14 | K14: =SUMPRODUCT((Fixtures!D$5:D$76=B14)*(Fixtures!E$5:E$76<>"")*(Fixtures!F$5:F$76<>"")*((Fixtures!E$5:E$76>Fixtures!F$5:F$76)*3+(Fixtures!E$5:E$76=Fixtures!F$5:F$76)*2))+SUMPRODUCT((Fixtures!G$5:G$76=B14)*(Fixtures!E$5:E$76<>"")*(Fixtures!F$5:F$76<>"")*((Fixtures!F$5:F$76>Fixtures!E$5:E$76)*3+(Fixtures!E$5:E$76=Fixtures!F$5:F$76)*2))
A15: 11 | B15: Haiti | C15: Group C | D15: =COUNTIFS(Fixtures!D$5:D$76,B15,Fixtures!E$5:E$76,"<>")+COUNTIFS(Fixtures!G$5:G$76,B15,Fixtures!F$5:F$76,"<>") | E15: =COUNTIFS(Fixtures!D$5:D$76,B15,Fixtures!J$5:J$76,"W")+COUNTIFS(Fixtures!G$5:G$76,B15,Fixtures!K$5:K$76,"W") | F15: =COUNTIFS(Fixtures!D$5:D$76,B15,Fixtures!J$5:J$76,"D")+COUNTIFS(Fixtures!G$5:G$76,B15,Fixtures!K$5:K$76,"D") | G15: =COUNTIFS(Fixtures!D$5:D$76,B15,Fixtures!J$5:J$76,"L")+COUNTIFS(Fixtures!G$5:G$76,B15,Fixtures!K$5:K$76,"L") | H15: =SUMPRODUCT((Fixtures!D$5:D$76=B15)*(Fixtures!E$5:E$76<>"")*Fixtures!E$5:E$76)+SUMPRODUCT((Fixtures!G$5:G$76=B15)*(Fixtures!F$5:F$76<>"")*Fixtures!F$5:F$76) | I15: =SUMPRODUCT((Fixtures!D$5:D$76=B15)*(Fixtures!F$5:F$76<>"")*Fixtures!F$5:F$76)+SUMPRODUCT((Fixtures!G$5:G$76=B15)*(Fixtures!E$5:E$76<>"")*Fixtures!E$5:E$76) | J15: =H15-I15 | K15: =SUMPRODUCT((Fixtures!D$5:D$76=B15)*(Fixtures!E$5:E$76<>"")*(Fixtures!F$5:F$76<>"")*((Fixtures!E$5:E$76>Fixtures!F$5:F$76)*3+(Fixtures!E$5:E$76=Fixtures!F$5:F$76)*2))+SUMPRODUCT((Fixtures!G$5:G$76=B15)*(Fixtures!E$5:E$76<>"")*(Fixtures!F$5:F$76<>"")*((Fixtures!F$5:F$76>Fixtures!E$5:E$76)*3+(Fixtures!E$5:E$76=Fixtures!F$5:F$76)*2))
A16: 12 | B16: Scotland | C16: Group C | D16: =COUNTIFS(Fixtures!D$5:D$76,B16,Fixtures!E$5:E$76,"<>")+COUNTIFS(Fixtures!G$5:G$76,B16,Fixtures!F$5:F$76,"<>") | E16: =COUNTIFS(Fixtures!D$5:D$76,B16,Fixtures!J$5:J$76,"W")+COUNTIFS(Fixtures!G$5:G$76,B16,Fixtures!K$5:K$76,"W") | F16: =COUNTIFS(Fixtures!D$5:D$76,B16,Fixtures!J$5:J$76,"D")+COUNTIFS(Fixtures!G$5:G$76,B16,Fixtures!K$5:K$76,"D") | G16: =COUNTIFS(Fixtures!D$5:D$76,B16,Fixtures!J$5:J$76,"L")+COUNTIFS(Fixtures!G$5:G$76,B16,Fixtures!K$5:K$76,"L") | H16: =SUMPRODUCT((Fixtures!D$5:D$76=B16)*(Fixtures!E$5:E$76<>"")*Fixtures!E$5:E$76)+SUMPRODUCT((Fixtures!G$5:G$76=B16)*(Fixtures!F$5:F$76<>"")*Fixtures!F$5:F$76) | I16: =SUMPRODUCT((Fixtures!D$5:D$76=B16)*(Fixtures!F$5:F$76<>"")*Fixtures!F$5:F$76)+SUMPRODUCT((Fixtures!G$5:G$76=B16)*(Fixtures!E$5:E$76<>"")*Fixtures!E$5:E$76) | J16: =H16-I16 | K16: =SUMPRODUCT((Fixtures!D$5:D$76=B16)*(Fixtures!E$5:E$76<>"")*(Fixtures!F$5:F$76<>"")*((Fixtures!E$5:E$76>Fixtures!F$5:F$76)*3+(Fixtures!E$5:E$76=Fixtures!F$5:F$76)*2))+SUMPRODUCT((Fixtures!G$5:G$76=B16)*(Fixtures!E$5:E$76<>"")*(Fixtures!F$5:F$76<>"")*((Fixtures!F$5:F$76>Fixtures!E$5:E$76)*3+(Fixtures!E$5:E$76=Fixtures!F$5:F$76)*2))
... A52: 48 | B52: Panama | C52: Group L | D52: =COUNTIFS(Fixtures!D$5:D$76,B52,Fixtures!E$5:E$76,"<>")+COUNTIFS(Fixtures!G$5:G$76,B52,Fixtures!F$5:F$76,"<>") | E52: =COUNTIFS(Fixtures!D$5:D$76,B52,Fixtures!J$5:J$76,"W")+COUNTIFS(Fixtures!G$5:G$76,B52,Fixtures!K$5:K$76,"W") | F52: =COUNTIFS(Fixtures!D$5:D$76,B52,Fixtures!J$5:J$76,"D")+COUNTIFS(Fixtures!G$5:G$76,B52,Fixtures!K$5:K$76,"D") | G52: =COUNTIFS(Fixtures!D$5:D$76,B52,Fixtures!J$5:J$76,"L")+COUNTIFS(Fixtures!G$5:G$76,B52,Fixtures!K$5:K$76,"L") | H52: =SUMPRODUCT((Fixtures!D$5:D$76=B52)*(Fixtures!E$5:E$76<>"")*Fixtures!E$5:E$76)+SUMPRODUCT((Fixtures!G$5:G$76=B52)*(Fixtures!F$5:F$76<>"")*Fixtures!F$5:F$76) | I52: =SUMPRODUCT((Fixtures!D$5:D$76=B52)*(Fixtures!F$5:F$76<>"")*Fixtures!F$5:F$76)+SUMPRODUCT((Fixtures!G$5:G$76=B52)*(Fixtures!E$5:E$76<>"")*Fixtures!E$5:E$76) | J52: =H52-I52 | K52: =SUMPRODUCT((Fixtures!D$5:D$76=B52)*(Fixtures!E$5:E$76<>"")*(Fixtures!F$5:F$76<>"")*((Fixtures!E$5:E$76>Fixtures!F$5:F$76)*3+(Fixtures!E$5:E$76=Fixtures!F$5:F$76)*2))+SUMPRODUCT((Fixtures!G$5:G$76=B52)*(Fixtures!E$5:E$76<>"")*(Fixtures!F$5:F$76<>"")*((Fixtures!F$5:F$76>Fixtures!E$5:E$76)*3+(Fixtures!E$5:E$76=Fixtures!F$5:F$76)*2))

Sheet Leaderboard
A1: SWEEPSTAKE LEADERBOARD
A2: Auto-ranked — highest points always shown first.
A4: Rank | B4: Participant | C4: Team(s) | D4: Total Points | E4: Wins | F4: Draws | H4: Participant | I4: Team | J4: Points | K4: Wins | L4: Draws | M4: GD | N4: Rank
A5: 1 | B5: =IFERROR(INDEX($H$5:$H$104,MATCH(1,$N$5:$N$104,0)),"") | C5: =IFERROR(INDEX($I$5:$I$104,MATCH(1,$N$5:$N$104,0)),"") | D5: =IFERROR(INDEX($J$5:$J$104,MATCH(1,$N$5:$N$104,0)),"") | E5: =IFERROR(INDEX($K$5:$K$104,MATCH(1,$N$5:$N$104,0)),"") | F5: =IFERROR(INDEX($L$5:$L$104,MATCH(1,$N$5:$N$104,0)),"") | H5: =IF(Allocation!B6="","",Allocation!B6) | I5: =IF(Allocation!C6="","",Allocation!C6) | J5: =IF(I5="","",SUMPRODUCT((Fixtures!D$5:D$76=I5)*(Fixtures!E$5:E$76<>"")*(Fixtures!F$5:F$76<>"")*((Fixtures!E$5:E$76>Fixtures!F$5:F$76)*3+(Fixtures!E$5:E$76=Fixtures!F$5:F$76)*2))+SUMPRODUCT((Fixtures!G$5:G$76=I5)*(Fixtures!E$5:E$76<>"")*(Fixtures!F$5:F$76<>"")*((Fixtures!F$5:F$76>Fixtures!E$5:E$76)*3+(Fixtures!E$5:E$76=Fixtures!F$5:F$76)*2))) | K5: =IF(I5="","",COUNTIFS(Fixtures!D$5:D$76,I5,Fixtures!J$5:J$76,"W")+COUNTIFS(Fixtures!G$5:G$76,I5,Fixtures!K$5:K$76,"W")) | L5: =IF(I5="","",COUNTIFS(Fixtures!D$5:D$76,I5,Fixtures!J$5:J$76,"D")+COUNTIFS(Fixtures!G$5:G$76,I5,Fixtures!K$5:K$76,"D")) | M5: =IF(I5="","",SUMPRODUCT((Fixtures!D$5:D$76=I5)*(Fixtures!E$5:E$76<>"")*(Fixtures!F$5:F$76<>"")*(Fixtures!E$5:E$76-Fixtures!F$5:F$76))+SUMPRODUCT((Fixtures!G$5:G$76=I5)*(Fixtures!E$5:E$76<>"")*(Fixtures!F$5:F$76<>"")*(Fixtures!F$5:F$76-Fixtures!E$5:E$76))) | N5: =IF(H5="","",COUNTIFS($J$5:$J$104,">"&J5,$H$5:$H$104,"<>")+COUNTIFS($J$5:$J5,J5,$H$5:$H5,"<>"))
A6: 2 | B6: =IFERROR(INDEX($H$5:$H$104,MATCH(2,$N$5:$N$104,0)),"") | C6: =IFERROR(INDEX($I$5:$I$104,MATCH(2,$N$5:$N$104,0)),"") | D6: =IFERROR(INDEX($J$5:$J$104,MATCH(2,$N$5:$N$104,0)),"") | E6: =IFERROR(INDEX($K$5:$K$104,MATCH(2,$N$5:$N$104,0)),"") | F6: =IFERROR(INDEX($L$5:$L$104,MATCH(2,$N$5:$N$104,0)),"") | H6: =IF(Allocation!B7="","",Allocation!B7) | I6: =IF(Allocation!C7="","",Allocation!C7) | J6: =IF(I6="","",SUMPRODUCT((Fixtures!D$5:D$76=I6)*(Fixtures!E$5:E$76<>"")*(Fixtures!F$5:F$76<>"")*((Fixtures!E$5:E$76>Fixtures!F$5:F$76)*3+(Fixtures!E$5:E$76=Fixtures!F$5:F$76)*2))+SUMPRODUCT((Fixtures!G$5:G$76=I6)*(Fixtures!E$5:E$76<>"")*(Fixtures!F$5:F$76<>"")*((Fixtures!F$5:F$76>Fixtures!E$5:E$76)*3+(Fixtures!E$5:E$76=Fixtures!F$5:F$76)*2))) | K6: =IF(I6="","",COUNTIFS(Fixtures!D$5:D$76,I6,Fixtures!J$5:J$76,"W")+COUNTIFS(Fixtures!G$5:G$76,I6,Fixtures!K$5:K$76,"W")) | L6: =IF(I6="","",COUNTIFS(Fixtures!D$5:D$76,I6,Fixtures!J$5:J$76,"D")+COUNTIFS(Fixtures!G$5:G$76,I6,Fixtures!K$5:K$76,"D")) | M6: =IF(I6="","",SUMPRODUCT((Fixtures!D$5:D$76=I6)*(Fixtures!E$5:E$76<>"")*(Fixtures!F$5:F$76<>"")*(Fixtures!E$5:E$76-Fixtures!F$5:F$76))+SUMPRODUCT((Fixtures!G$5:G$76=I6)*(Fixtures!E$5:E$76<>"")*(Fixtures!F$5:F$76<>"")*(Fixtures!F$5:F$76-Fixtures!E$5:E$76))) | N6: =IF(H6="","",COUNTIFS($J$5:$J$104,">"&J6,$H$5:$H$104,"<>")+COUNTIFS($J$5:$J6,J6,$H$5:$H6,"<>"))
A7: 3 | B7: =IFERROR(INDEX($H$5:$H$104,MATCH(3,$N$5:$N$104,0)),"") | C7: =IFERROR(INDEX($I$5:$I$104,MATCH(3,$N$5:$N$104,0)),"") | D7: =IFERROR(INDEX($J$5:$J$104,MATCH(3,$N$5:$N$104,0)),"") | E7: =IFERROR(INDEX($K$5:$K$104,MATCH(3,$N$5:$N$104,0)),"") | F7: =IFERROR(INDEX($L$5:$L$104,MATCH(3,$N$5:$N$104,0)),"") | H7: =IF(Allocation!B8="","",Allocation!B8) | I7: =IF(Allocation!C8="","",Allocation!C8) | J7: =IF(I7="","",SUMPRODUCT((Fixtures!D$5:D$76=I7)*(Fixtures!E$5:E$76<>"")*(Fixtures!F$5:F$76<>"")*((Fixtures!E$5:E$76>Fixtures!F$5:F$76)*3+(Fixtures!E$5:E$76=Fixtures!F$5:F$76)*2))+SUMPRODUCT((Fixtures!G$5:G$76=I7)*(Fixtures!E$5:E$76<>"")*(Fixtures!F$5:F$76<>"")*((Fixtures!F$5:F$76>Fixtures!E$5:E$76)*3+(Fixtures!E$5:E$76=Fixtures!F$5:F$76)*2))) | K7: =IF(I7="","",COUNTIFS(Fixtures!D$5:D$76,I7,Fixtures!J$5:J$76,"W")+COUNTIFS(Fixtures!G$5:G$76,I7,Fixtures!K$5:K$76,"W")) | L7: =IF(I7="","",COUNTIFS(Fixtures!D$5:D$76,I7,Fixtures!J$5:J$76,"D")+COUNTIFS(Fixtures!G$5:G$76,I7,Fixtures!K$5:K$76,"D")) | M7: =IF(I7="","",SUMPRODUCT((Fixtures!D$5:D$76=I7)*(Fixtures!E$5:E$76<>"")*(Fixtures!F$5:F$76<>"")*(Fixtures!E$5:E$76-Fixtures!F$5:F$76))+SUMPRODUCT((Fixtures!G$5:G$76=I7)*(Fixtures!E$5:E$76<>"")*(Fixtures!F$5:F$76<>"")*(Fixtures!F$5:F$76-Fixtures!E$5:E$76))) | N7: =IF(H7="","",COUNTIFS($J$5:$J$104,">"&J7,$H$5:$H$104,"<>")+COUNTIFS($J$5:$J7,J7,$H$5:$H7,"<>"))
A8: 4 | B8: =IFERROR(INDEX($H$5:$H$104,MATCH(4,$N$5:$N$104,0)),"") | C8: =IFERROR(INDEX($I$5:$I$104,MATCH(4,$N$5:$N$104,0)),"") | D8: =IFERROR(INDEX($J$5:$J$104,MATCH(4,$N$5:$N$104,0)),"") | E8: =IFERROR(INDEX($K$5:$K$104,MATCH(4,$N$5:$N$104,0)),"") | F8: =IFERROR(INDEX($L$5:$L$104,MATCH(4,$N$5:$N$104,0)),"") | H8: =IF(Allocation!B9="","",Allocation!B9) | I8: =IF(Allocation!C9="","",Allocation!C9) | J8: =IF(I8="","",SUMPRODUCT((Fixtures!D$5:D$76=I8)*(Fixtures!E$5:E$76<>"")*(Fixtures!F$5:F$76<>"")*((Fixtures!E$5:E$76>Fixtures!F$5:F$76)*3+(Fixtures!E$5:E$76=Fixtures!F$5:F$76)*2))+SUMPRODUCT((Fixtures!G$5:G$76=I8)*(Fixtures!E$5:E$76<>"")*(Fixtures!F$5:F$76<>"")*((Fixtures!F$5:F$76>Fixtures!E$5:E$76)*3+(Fixtures!E$5:E$76=Fixtures!F$5:F$76)*2))) | K8: =IF(I8="","",COUNTIFS(Fixtures!D$5:D$76,I8,Fixtures!J$5:J$76,"W")+COUNTIFS(Fixtures!G$5:G$76,I8,Fixtures!K$5:K$76,"W")) | L8: =IF(I8="","",COUNTIFS(Fixtures!D$5:D$76,I8,Fixtures!J$5:J$76,"D")+COUNTIFS(Fixtures!G$5:G$76,I8,Fixtures!K$5:K$76,"D")) | M8: =IF(I8="","",SUMPRODUCT((Fixtures!D$5:D$76=I8)*(Fixtures!E$5:E$76<>"")*(Fixtures!F$5:F$76<>"")*(Fixtures!E$5:E$76-Fixtures!F$5:F$76))+SUMPRODUCT((Fixtures!G$5:G$76=I8)*(Fixtures!E$5:E$76<>"")*(Fixtures!F$5:F$76<>"")*(Fixtures!F$5:F$76-Fixtures!E$5:E$76))) | N8: =IF(H8="","",COUNTIFS($J$5:$J$104,">"&J8,$H$5:$H$104,"<>")+COUNTIFS($J$5:$J8,J8,$H$5:$H8,"<>"))
A9: 5 | B9: =IFERROR(INDEX($H$5:$H$104,MATCH(5,$N$5:$N$104,0)),"") | C9: =IFERROR(INDEX($I$5:$I$104,MATCH(5,$N$5:$N$104,0)),"") | D9: =IFERROR(INDEX($J$5:$J$104,MATCH(5,$N$5:$N$104,0)),"") | E9: =IFERROR(INDEX($K$5:$K$104,MATCH(5,$N$5:$N$104,0)),"") | F9: =IFERROR(INDEX($L$5:$L$104,MATCH(5,$N$5:$N$104,0)),"") | H9: =IF(Allocation!B10="","",Allocation!B10) | I9: =IF(Allocation!C10="","",Allocation!C10) | J9: =IF(I9="","",SUMPRODUCT((Fixtures!D$5:D$76=I9)*(Fixtures!E$5:E$76<>"")*(Fixtures!F$5:F$76<>"")*((Fixtures!E$5:E$76>Fixtures!F$5:F$76)*3+(Fixtures!E$5:E$76=Fixtures!F$5:F$76)*2))+SUMPRODUCT((Fixtures!G$5:G$76=I9)*(Fixtures!E$5:E$76<>"")*(Fixtures!F$5:F$76<>"")*((Fixtures!F$5:F$76>Fixtures!E$5:E$76)*3+(Fixtures!E$5:E$76=Fixtures!F$5:F$76)*2))) | K9: =IF(I9="","",COUNTIFS(Fixtures!D$5:D$76,I9,Fixtures!J$5:J$76,"W")+COUNTIFS(Fixtures!G$5:G$76,I9,Fixtures!K$5:K$76,"W")) | L9: =IF(I9="","",COUNTIFS(Fixtures!D$5:D$76,I9,Fixtures!J$5:J$76,"D")+COUNTIFS(Fixtures!G$5:G$76,I9,Fixtures!K$5:K$76,"D")) | M9: =IF(I9="","",SUMPRODUCT((Fixtures!D$5:D$76=I9)*(Fixtures!E$5:E$76<>"")*(Fixtures!F$5:F$76<>"")*(Fixtures!E$5:E$76-Fixtures!F$5:F$76))+SUMPRODUCT((Fixtures!G$5:G$76=I9)*(Fixtures!E$5:E$76<>"")*(Fixtures!F$5:F$76<>"")*(Fixtures!F$5:F$76-Fixtures!E$5:E$76))) | N9: =IF(H9="","",COUNTIFS($J$5:$J$104,">"&J9,$H$5:$H$104,"<>")+COUNTIFS($J$5:$J9,J9,$H$5:$H9,"<>"))
A10: 6 | B10: =IFERROR(INDEX($H$5:$H$104,MATCH(6,$N$5:$N$104,0)),"") | C10: =IFERROR(INDEX($I$5:$I$104,MATCH(6,$N$5:$N$104,0)),"") | D10: =IFERROR(INDEX($J$5:$J$104,MATCH(6,$N$5:$N$104,0)),"") | E10: =IFERROR(INDEX($K$5:$K$104,MATCH(6,$N$5:$N$104,0)),"") | F10: =IFERROR(INDEX($L$5:$L$104,MATCH(6,$N$5:$N$104,0)),"") | H10: =IF(Allocation!B11="","",Allocation!B11) | I10: =IF(Allocation!C11="","",Allocation!C11) | J10: =IF(I10="","",SUMPRODUCT((Fixtures!D$5:D$76=I10)*(Fixtures!E$5:E$76<>"")*(Fixtures!F$5:F$76<>"")*((Fixtures!E$5:E$76>Fixtures!F$5:F$76)*3+(Fixtures!E$5:E$76=Fixtures!F$5:F$76)*2))+SUMPRODUCT((Fixtures!G$5:G$76=I10)*(Fixtures!E$5:E$76<>"")*(Fixtures!F$5:F$76<>"")*((Fixtures!F$5:F$76>Fixtures!E$5:E$76)*3+(Fixtures!E$5:E$76=Fixtures!F$5:F$76)*2))) | K10: =IF(I10="","",COUNTIFS(Fixtures!D$5:D$76,I10,Fixtures!J$5:J$76,"W")+COUNTIFS(Fixtures!G$5:G$76,I10,Fixtures!K$5:K$76,"W")) | L10: =IF(I10="","",COUNTIFS(Fixtures!D$5:D$76,I10,Fixtures!J$5:J$76,"D")+COUNTIFS(Fixtures!G$5:G$76,I10,Fixtures!K$5:K$76,"D")) | M10: =IF(I10="","",SUMPRODUCT((Fixtures!D$5:D$76=I10)*(Fixtures!E$5:E$76<>"")*(Fixtures!F$5:F$76<>"")*(Fixtures!E$5:E$76-Fixtures!F$5:F$76))+SUMPRODUCT((Fixtures!G$5:G$76=I10)*(Fixtures!E$5:E$76<>"")*(Fixtures!F$5:F$76<>"")*(Fixtures!F$5:F$76-Fixtures!E$5:E$76))) | N10: =IF(H10="","",COUNTIFS($J$5:$J$104,">"&J10,$H$5:$H$104,"<>")+COUNTIFS($J$5:$J10,J10,$H$5:$H10,"<>"))
A11: 7 | B11: =IFERROR(INDEX($H$5:$H$104,MATCH(7,$N$5:$N$104,0)),"") | C11: =IFERROR(INDEX($I$5:$I$104,MATCH(7,$N$5:$N$104,0)),"") | D11: =IFERROR(INDEX($J$5:$J$104,MATCH(7,$N$5:$N$104,0)),"") | E11: =IFERROR(INDEX($K$5:$K$104,MATCH(7,$N$5:$N$104,0)),"") | F11: =IFERROR(INDEX($L$5:$L$104,MATCH(7,$N$5:$N$104,0)),"") | H11: =IF(Allocation!B12="","",Allocation!B12) | I11: =IF(Allocation!C12="","",Allocation!C12) | J11: =IF(I11="","",SUMPRODUCT((Fixtures!D$5:D$76=I11)*(Fixtures!E$5:E$76<>"")*(Fixtures!F$5:F$76<>"")*((Fixtures!E$5:E$76>Fixtures!F$5:F$76)*3+(Fixtures!E$5:E$76=Fixtures!F$5:F$76)*2))+SUMPRODUCT((Fixtures!G$5:G$76=I11)*(Fixtures!E$5:E$76<>"")*(Fixtures!F$5:F$76<>"")*((Fixtures!F$5:F$76>Fixtures!E$5:E$76)*3+(Fixtures!E$5:E$76=Fixtures!F$5:F$76)*2))) | K11: =IF(I11="","",COUNTIFS(Fixtures!D$5:D$76,I11,Fixtures!J$5:J$76,"W")+COUNTIFS(Fixtures!G$5:G$76,I11,Fixtures!K$5:K$76,"W")) | L11: =IF(I11="","",COUNTIFS(Fixtures!D$5:D$76,I11,Fixtures!J$5:J$76,"D")+COUNTIFS(Fixtures!G$5:G$76,I11,Fixtures!K$5:K$76,"D")) | M11: =IF(I11="","",SUMPRODUCT((Fixtures!D$5:D$76=I11)*(Fixtures!E$5:E$76<>"")*(Fixtures!F$5:F$76<>"")*(Fixtures!E$5:E$76-Fixtures!F$5:F$76))+SUMPRODUCT((Fixtures!G$5:G$76=I11)*(Fixtures!E$5:E$76<>"")*(Fixtures!F$5:F$76<>"")*(Fixtures!F$5:F$76-Fixtures!E$5:E$76))) | N11: =IF(H11="","",COUNTIFS($J$5:$J$104,">"&J11,$H$5:$H$104,"<>")+COUNTIFS($J$5:$J11,J11,$H$5:$H11,"<>"))
A12: 8 | B12: =IFERROR(INDEX($H$5:$H$104,MATCH(8,$N$5:$N$104,0)),"") | C12: =IFERROR(INDEX($I$5:$I$104,MATCH(8,$N$5:$N$104,0)),"") | D12: =IFERROR(INDEX($J$5:$J$104,MATCH(8,$N$5:$N$104,0)),"") | E12: =IFERROR(INDEX($K$5:$K$104,MATCH(8,$N$5:$N$104,0)),"") | F12: =IFERROR(INDEX($L$5:$L$104,MATCH(8,$N$5:$N$104,0)),"") | H12: =IF(Allocation!B13="","",Allocation!B13) | I12: =IF(Allocation!C13="","",Allocation!C13) | J12: =IF(I12="","",SUMPRODUCT((Fixtures!D$5:D$76=I12)*(Fixtures!E$5:E$76<>"")*(Fixtures!F$5:F$76<>"")*((Fixtures!E$5:E$76>Fixtures!F$5:F$76)*3+(Fixtures!E$5:E$76=Fixtures!F$5:F$76)*2))+SUMPRODUCT((Fixtures!G$5:G$76=I12)*(Fixtures!E$5:E$76<>"")*(Fixtures!F$5:F$76<>"")*((Fixtures!F$5:F$76>Fixtures!E$5:E$76)*3+(Fixtures!E$5:E$76=Fixtures!F$5:F$76)*2))) | K12: =IF(I12="","",COUNTIFS(Fixtures!D$5:D$76,I12,Fixtures!J$5:J$76,"W")+COUNTIFS(Fixtures!G$5:G$76,I12,Fixtures!K$5:K$76,"W")) | L12: =IF(I12="","",COUNTIFS(Fixtures!D$5:D$76,I12,Fixtures!J$5:J$76,"D")+COUNTIFS(Fixtures!G$5:G$76,I12,Fixtures!K$5:K$76,"D")) | M12: =IF(I12="","",SUMPRODUCT((Fixtures!D$5:D$76=I12)*(Fixtures!E$5:E$76<>"")*(Fixtures!F$5:F$76<>"")*(Fixtures!E$5:E$76-Fixtures!F$5:F$76))+SUMPRODUCT((Fixtures!G$5:G$76=I12)*(Fixtures!E$5:E$76<>"")*(Fixtures!F$5:F$76<>"")*(Fixtures!F$5:F$76-Fixtures!E$5:E$76))) | N12: =IF(H12="","",COUNTIFS($J$5:$J$104,">"&J12,$H$5:$H$104,"<>")+COUNTIFS($J$5:$J12,J12,$H$5:$H12,"<>"))
A13: 9 | B13: =IFERROR(INDEX($H$5:$H$104,MATCH(9,$N$5:$N$104,0)),"") | C13: =IFERROR(INDEX($I$5:$I$104,MATCH(9,$N$5:$N$104,0)),"") | D13: =IFERROR(INDEX($J$5:$J$104,MATCH(9,$N$5:$N$104,0)),"") | E13: =IFERROR(INDEX($K$5:$K$104,MATCH(9,$N$5:$N$104,0)),"") | F13: =IFERROR(INDEX($L$5:$L$104,MATCH(9,$N$5:$N$104,0)),"") | H13: =IF(Allocation!B14="","",Allocation!B14) | I13: =IF(Allocation!C14="","",Allocation!C14) | J13: =IF(I13="","",SUMPRODUCT((Fixtures!D$5:D$76=I13)*(Fixtures!E$5:E$76<>"")*(Fixtures!F$5:F$76<>"")*((Fixtures!E$5:E$76>Fixtures!F$5:F$76)*3+(Fixtures!E$5:E$76=Fixtures!F$5:F$76)*2))+SUMPRODUCT((Fixtures!G$5:G$76=I13)*(Fixtures!E$5:E$76<>"")*(Fixtures!F$5:F$76<>"")*((Fixtures!F$5:F$76>Fixtures!E$5:E$76)*3+(Fixtures!E$5:E$76=Fixtures!F$5:F$76)*2))) | K13: =IF(I13="","",COUNTIFS(Fixtures!D$5:D$76,I13,Fixtures!J$5:J$76,"W")+COUNTIFS(Fixtures!G$5:G$76,I13,Fixtures!K$5:K$76,"W")) | L13: =IF(I13="","",COUNTIFS(Fixtures!D$5:D$76,I13,Fixtures!J$5:J$76,"D")+COUNTIFS(Fixtures!G$5:G$76,I13,Fixtures!K$5:K$76,"D")) | M13: =IF(I13="","",SUMPRODUCT((Fixtures!D$5:D$76=I13)*(Fixtures!E$5:E$76<>"")*(Fixtures!F$5:F$76<>"")*(Fixtures!E$5:E$76-Fixtures!F$5:F$76))+SUMPRODUCT((Fixtures!G$5:G$76=I13)*(Fixtures!E$5:E$76<>"")*(Fixtures!F$5:F$76<>"")*(Fixtures!F$5:F$76-Fixtures!E$5:E$76))) | N13: =IF(H13="","",COUNTIFS($J$5:$J$104,">"&J13,$H$5:$H$104,"<>")+COUNTIFS($J$5:$J13,J13,$H$5:$H13,"<>"))
A14: 10 | B14: =IFERROR(INDEX($H$5:$H$104,MATCH(10,$N$5:$N$104,0)),"") | C14: =IFERROR(INDEX($I$5:$I$104,MATCH(10,$N$5:$N$104,0)),"") | D14: =IFERROR(INDEX($J$5:$J$104,MATCH(10,$N$5:$N$104,0)),"") | E14: =IFERROR(INDEX($K$5:$K$104,MATCH(10,$N$5:$N$104,0)),"") | F14: =IFERROR(INDEX($L$5:$L$104,MATCH(10,$N$5:$N$104,0)),"") | H14: =IF(Allocation!B15="","",Allocation!B15) | I14: =IF(Allocation!C15="","",Allocation!C15) | J14: =IF(I14="","",SUMPRODUCT((Fixtures!D$5:D$76=I14)*(Fixtures!E$5:E$76<>"")*(Fixtures!F$5:F$76<>"")*((Fixtures!E$5:E$76>Fixtures!F$5:F$76)*3+(Fixtures!E$5:E$76=Fixtures!F$5:F$76)*2))+SUMPRODUCT((Fixtures!G$5:G$76=I14)*(Fixtures!E$5:E$76<>"")*(Fixtures!F$5:F$76<>"")*((Fixtures!F$5:F$76>Fixtures!E$5:E$76)*3+(Fixtures!E$5:E$76=Fixtures!F$5:F$76)*2))) | K14: =IF(I14="","",COUNTIFS(Fixtures!D$5:D$76,I14,Fixtures!J$5:J$76,"W")+COUNTIFS(Fixtures!G$5:G$76,I14,Fixtures!K$5:K$76,"W")) | L14: =IF(I14="","",COUNTIFS(Fixtures!D$5:D$76,I14,Fixtures!J$5:J$76,"D")+COUNTIFS(Fixtures!G$5:G$76,I14,Fixtures!K$5:K$76,"D")) | M14: =IF(I14="","",SUMPRODUCT((Fixtures!D$5:D$76=I14)*(Fixtures!E$5:E$76<>"")*(Fixtures!F$5:F$76<>"")*(Fixtures!E$5:E$76-Fixtures!F$5:F$76))+SUMPRODUCT((Fixtures!G$5:G$76=I14)*(Fixtures!E$5:E$76<>"")*(Fixtures!F$5:F$76<>"")*(Fixtures!F$5:F$76-Fixtures!E$5:E$76))) | N14: =IF(H14="","",COUNTIFS($J$5:$J$104,">"&J14,$H$5:$H$104,"<>")+COUNTIFS($J$5:$J14,J14,$H$5:$H14,"<>"))
A15: 11 | B15: =IFERROR(INDEX($H$5:$H$104,MATCH(11,$N$5:$N$104,0)),"") | C15: =IFERROR(INDEX($I$5:$I$104,MATCH(11,$N$5:$N$104,0)),"") | D15: =IFERROR(INDEX($J$5:$J$104,MATCH(11,$N$5:$N$104,0)),"") | E15: =IFERROR(INDEX($K$5:$K$104,MATCH(11,$N$5:$N$104,0)),"") | F15: =IFERROR(INDEX($L$5:$L$104,MATCH(11,$N$5:$N$104,0)),"") | H15: =IF(Allocation!B16="","",Allocation!B16) | I15: =IF(Allocation!C16="","",Allocation!C16) | J15: =IF(I15="","",SUMPRODUCT((Fixtures!D$5:D$76=I15)*(Fixtures!E$5:E$76<>"")*(Fixtures!F$5:F$76<>"")*((Fixtures!E$5:E$76>Fixtures!F$5:F$76)*3+(Fixtures!E$5:E$76=Fixtures!F$5:F$76)*2))+SUMPRODUCT((Fixtures!G$5:G$76=I15)*(Fixtures!E$5:E$76<>"")*(Fixtures!F$5:F$76<>"")*((Fixtures!F$5:F$76>Fixtures!E$5:E$76)*3+(Fixtures!E$5:E$76=Fixtures!F$5:F$76)*2))) | K15: =IF(I15="","",COUNTIFS(Fixtures!D$5:D$76,I15,Fixtures!J$5:J$76,"W")+COUNTIFS(Fixtures!G$5:G$76,I15,Fixtures!K$5:K$76,"W")) | L15: =IF(I15="","",COUNTIFS(Fixtures!D$5:D$76,I15,Fixtures!J$5:J$76,"D")+COUNTIFS(Fixtures!G$5:G$76,I15,Fixtures!K$5:K$76,"D")) | M15: =IF(I15="","",SUMPRODUCT((Fixtures!D$5:D$76=I15)*(Fixtures!E$5:E$76<>"")*(Fixtures!F$5:F$76<>"")*(Fixtures!E$5:E$76-Fixtures!F$5:F$76))+SUMPRODUCT((Fixtures!G$5:G$76=I15)*(Fixtures!E$5:E$76<>"")*(Fixtures!F$5:F$76<>"")*(Fixtures!F$5:F$76-Fixtures!E$5:E$76))) | N15: =IF(H15="","",COUNTIFS($J$5:$J$104,">"&J15,$H$5:$H$104,"<>")+COUNTIFS($J$5:$J15,J15,$H$5:$H15,"<>"))
A16: 12 | B16: =IFERROR(INDEX($H$5:$H$104,MATCH(12,$N$5:$N$104,0)),"") | C16: =IFERROR(INDEX($I$5:$I$104,MATCH(12,$N$5:$N$104,0)),"") | D16: =IFERROR(INDEX($J$5:$J$104,MATCH(12,$N$5:$N$104,0)),"") | E16: =IFERROR(INDEX($K$5:$K$104,MATCH(12,$N$5:$N$104,0)),"") | F16: =IFERROR(INDEX($L$5:$L$104,MATCH(12,$N$5:$N$104,0)),"") | H16: =IF(Allocation!B17="","",Allocation!B17) | I16: =IF(Allocation!C17="","",Allocation!C17) | J16: =IF(I16="","",SUMPRODUCT((Fixtures!D$5:D$76=I16)*(Fixtures!E$5:E$76<>"")*(Fixtures!F$5:F$76<>"")*((Fixtures!E$5:E$76>Fixtures!F$5:F$76)*3+(Fixtures!E$5:E$76=Fixtures!F$5:F$76)*2))+SUMPRODUCT((Fixtures!G$5:G$76=I16)*(Fixtures!E$5:E$76<>"")*(Fixtures!F$5:F$76<>"")*((Fixtures!F$5:F$76>Fixtures!E$5:E$76)*3+(Fixtures!E$5:E$76=Fixtures!F$5:F$76)*2))) | K16: =IF(I16="","",COUNTIFS(Fixtures!D$5:D$76,I16,Fixtures!J$5:J$76,"W")+COUNTIFS(Fixtures!G$5:G$76,I16,Fixtures!K$5:K$76,"W")) | L16: =IF(I16="","",COUNTIFS(Fixtures!D$5:D$76,I16,Fixtures!J$5:J$76,"D")+COUNTIFS(Fixtures!G$5:G$76,I16,Fixtures!K$5:K$76,"D")) | M16: =IF(I16="","",SUMPRODUCT((Fixtures!D$5:D$76=I16)*(Fixtures!E$5:E$76<>"")*(Fixtures!F$5:F$76<>"")*(Fixtures!E$5:E$76-Fixtures!F$5:F$76))+SUMPRODUCT((Fixtures!G$5:G$76=I16)*(Fixtures!E$5:E$76<>"")*(Fixtures!F$5:F$76<>"")*(Fixtures!F$5:F$76-Fixtures!E$5:E$76))) | N16: =IF(H16="","",COUNTIFS($J$5:$J$104,">"&J16,$H$5:$H$104,"<>")+COUNTIFS($J$5:$J16,J16,$H$5:$H16,"<>"))
A17: 13 | B17: =IFERROR(INDEX($H$5:$H$104,MATCH(13,$N$5:$N$104,0)),"") | C17: =IFERROR(INDEX($I$5:$I$104,MATCH(13,$N$5:$N$104,0)),"") | D17: =IFERROR(INDEX($J$5:$J$104,MATCH(13,$N$5:$N$104,0)),"") | E17: =IFERROR(INDEX($K$5:$K$104,MATCH(13,$N$5:$N$104,0)),"") | F17: =IFERROR(INDEX($L$5:$L$104,MATCH(13,$N$5:$N$104,0)),"") | H17: =IF(Allocation!B18="","",Allocation!B18) | I17: =IF(Allocation!C18="","",Allocation!C18) | J17: =IF(I17="","",SUMPRODUCT((Fixtures!D$5:D$76=I17)*(Fixtures!E$5:E$76<>"")*(Fixtures!F$5:F$76<>"")*((Fixtures!E$5:E$76>Fixtures!F$5:F$76)*3+(Fixtures!E$5:E$76=Fixtures!F$5:F$76)*2))+SUMPRODUCT((Fixtures!G$5:G$76=I17)*(Fixtures!E$5:E$76<>"")*(Fixtures!F$5:F$76<>"")*((Fixtures!F$5:F$76>Fixtures!E$5:E$76)*3+(Fixtures!E$5:E$76=Fixtures!F$5:F$76)*2))) | K17: =IF(I17="","",COUNTIFS(Fixtures!D$5:D$76,I17,Fixtures!J$5:J$76,"W")+COUNTIFS(Fixtures!G$5:G$76,I17,Fixtures!K$5:K$76,"W")) | L17: =IF(I17="","",COUNTIFS(Fixtures!D$5:D$76,I17,Fixtures!J$5:J$76,"D")+COUNTIFS(Fixtures!G$5:G$76,I17,Fixtures!K$5:K$76,"D")) | M17: =IF(I17="","",SUMPRODUCT((Fixtures!D$5:D$76=I17)*(Fixtures!E$5:E$76<>"")*(Fixtures!F$5:F$76<>"")*(Fixtures!E$5:E$76-Fixtures!F$5:F$76))+SUMPRODUCT((Fixtures!G$5:G$76=I17)*(Fixtures!E$5:E$76<>"")*(Fixtures!F$5:F$76<>"")*(Fixtures!F$5:F$76-Fixtures!E$5:E$76))) | N17: =IF(H17="","",COUNTIFS($J$5:$J$104,">"&J17,$H$5:$H$104,"<>")+COUNTIFS($J$5:$J17,J17,$H$5:$H17,"<>"))
A18: 14 | B18: =IFERROR(INDEX($H$5:$H$104,MATCH(14,$N$5:$N$104,0)),"") | C18: =IFERROR(INDEX($I$5:$I$104,MATCH(14,$N$5:$N$104,0)),"") | D18: =IFERROR(INDEX($J$5:$J$104,MATCH(14,$N$5:$N$104,0)),"") | E18: =IFERROR(INDEX($K$5:$K$104,MATCH(14,$N$5:$N$104,0)),"") | F18: =IFERROR(INDEX($L$5:$L$104,MATCH(14,$N$5:$N$104,0)),"") | H18: =IF(Allocation!B19="","",Allocation!B19) | I18: =IF(Allocation!C19="","",Allocation!C19) | J18: =IF(I18="","",SUMPRODUCT((Fixtures!D$5:D$76=I18)*(Fixtures!E$5:E$76<>"")*(Fixtures!F$5:F$76<>"")*((Fixtures!E$5:E$76>Fixtures!F$5:F$76)*3+(Fixtures!E$5:E$76=Fixtures!F$5:F$76)*2))+SUMPRODUCT((Fixtures!G$5:G$76=I18)*(Fixtures!E$5:E$76<>"")*(Fixtures!F$5:F$76<>"")*((Fixtures!F$5:F$76>Fixtures!E$5:E$76)*3+(Fixtures!E$5:E$76=Fixtures!F$5:F$76)*2))) | K18: =IF(I18="","",COUNTIFS(Fixtures!D$5:D$76,I18,Fixtures!J$5:J$76,"W")+COUNTIFS(Fixtures!G$5:G$76,I18,Fixtures!K$5:K$76,"W")) | L18: =IF(I18="","",COUNTIFS(Fixtures!D$5:D$76,I18,Fixtures!J$5:J$76,"D")+COUNTIFS(Fixtures!G$5:G$76,I18,Fixtures!K$5:K$76,"D")) | M18: =IF(I18="","",SUMPRODUCT((Fixtures!D$5:D$76=I18)*(Fixtures!E$5:E$76<>"")*(Fixtures!F$5:F$76<>"")*(Fixtures!E$5:E$76-Fixtures!F$5:F$76))+SUMPRODUCT((Fixtures!G$5:G$76=I18)*(Fixtures!E$5:E$76<>"")*(Fixtures!F$5:F$76<>"")*(Fixtures!F$5:F$76-Fixtures!E$5:E$76))) | N18: =IF(H18="","",COUNTIFS($J$5:$J$104,">"&J18,$H$5:$H$104,"<>")+COUNTIFS($J$5:$J18,J18,$H$5:$H18,"<>"))
A19: 15 | B19: =IFERROR(INDEX($H$5:$H$104,MATCH(15,$N$5:$N$104,0)),"") | C19: =IFERROR(INDEX($I$5:$I$104,MATCH(15,$N$5:$N$104,0)),"") | D19: =IFERROR(INDEX($J$5:$J$104,MATCH(15,$N$5:$N$104,0)),"") | E19: =IFERROR(INDEX($K$5:$K$104,MATCH(15,$N$5:$N$104,0)),"") | F19: =IFERROR(INDEX($L$5:$L$104,MATCH(15,$N$5:$N$104,0)),"") | H19: =IF(Allocation!B20="","",Allocation!B20) | I19: =IF(Allocation!C20="","",Allocation!C20) | J19: =IF(I19="","",SUMPRODUCT((Fixtures!D$5:D$76=I19)*(Fixtures!E$5:E$76<>"")*(Fixtures!F$5:F$76<>"")*((Fixtures!E$5:E$76>Fixtures!F$5:F$76)*3+(Fixtures!E$5:E$76=Fixtures!F$5:F$76)*2))+SUMPRODUCT((Fixtures!G$5:G$76=I19)*(Fixtures!E$5:E$76<>"")*(Fixtures!F$5:F$76<>"")*((Fixtures!F$5:F$76>Fixtures!E$5:E$76)*3+(Fixtures!E$5:E$76=Fixtures!F$5:F$76)*2))) | K19: =IF(I19="","",COUNTIFS(Fixtures!D$5:D$76,I19,Fixtures!J$5:J$76,"W")+COUNTIFS(Fixtures!G$5:G$76,I19,Fixtures!K$5:K$76,"W")) | L19: =IF(I19="","",COUNTIFS(Fixtures!D$5:D$76,I19,Fixtures!J$5:J$76,"D")+COUNTIFS(Fixtures!G$5:G$76,I19,Fixtures!K$5:K$76,"D")) | M19: =IF(I19="","",SUMPRODUCT((Fixtures!D$5:D$76=I19)*(Fixtures!E$5:E$76<>"")*(Fixtures!F$5:F$76<>"")*(Fixtures!E$5:E$76-Fixtures!F$5:F$76))+SUMPRODUCT((Fixtures!G$5:G$76=I19)*(Fixtures!E$5:E$76<>"")*(Fixtures!F$5:F$76<>"")*(Fixtures!F$5:F$76-Fixtures!E$5:E$76))) | N19: =IF(H19="","",COUNTIFS($J$5:$J$104,">"&J19,$H$5:$H$104,"<>")+COUNTIFS($J$5:$J19,J19,$H$5:$H19,"<>"))
A20: 16 | B20: =IFERROR(INDEX($H$5:$H$104,MATCH(16,$N$5:$N$104,0)),"") | C20: =IFERROR(INDEX($I$5:$I$104,MATCH(16,$N$5:$N$104,0)),"") | D20: =IFERROR(INDEX($J$5:$J$104,MATCH(16,$N$5:$N$104,0)),"") | E20: =IFERROR(INDEX($K$5:$K$104,MATCH(16,$N$5:$N$104,0)),"") | F20: =IFERROR(INDEX($L$5:$L$104,MATCH(16,$N$5:$N$104,0)),"") | H20: =IF(Allocation!B21="","",Allocation!B21) | I20: =IF(Allocation!C21="","",Allocation!C21) | J20: =IF(I20="","",SUMPRODUCT((Fixtures!D$5:D$76=I20)*(Fixtures!E$5:E$76<>"")*(Fixtures!F$5:F$76<>"")*((Fixtures!E$5:E$76>Fixtures!F$5:F$76)*3+(Fixtures!E$5:E$76=Fixtures!F$5:F$76)*2))+SUMPRODUCT((Fixtures!G$5:G$76=I20)*(Fixtures!E$5:E$76<>"")*(Fixtures!F$5:F$76<>"")*((Fixtures!F$5:F$76>Fixtures!E$5:E$76)*3+(Fixtures!E$5:E$76=Fixtures!F$5:F$76)*2))) | K20: =IF(I20="","",COUNTIFS(Fixtures!D$5:D$76,I20,Fixtures!J$5:J$76,"W")+COUNTIFS(Fixtures!G$5:G$76,I20,Fixtures!K$5:K$76,"W")) | L20: =IF(I20="","",COUNTIFS(Fixtures!D$5:D$76,I20,Fixtures!J$5:J$76,"D")+COUNTIFS(Fixtures!G$5:G$76,I20,Fixtures!K$5:K$76,"D")) | M20: =IF(I20="","",SUMPRODUCT((Fixtures!D$5:D$76=I20)*(Fixtures!E$5:E$76<>"")*(Fixtures!F$5:F$76<>"")*(Fixtures!E$5:E$76-Fixtures!F$5:F$76))+SUMPRODUCT((Fixtures!G$5:G$76=I20)*(Fixtures!E$5:E$76<>"")*(Fixtures!F$5:F$76<>"")*(Fixtures!F$5:F$76-Fixtures!E$5:E$76))) | N20: =IF(H20="","",COUNTIFS($J$5:$J$104,">"&J20,$H$5:$H$104,"<>")+COUNTIFS($J$5:$J20,J20,$H$5:$H20,"<>"))
A21: 17 | B21: =IFERROR(INDEX($H$5:$H$104,MATCH(17,$N$5:$N$104,0)),"") | C21: =IFERROR(INDEX($I$5:$I$104,MATCH(17,$N$5:$N$104,0)),"") | D21: =IFERROR(INDEX($J$5:$J$104,MATCH(17,$N$5:$N$104,0)),"") | E21: =IFERROR(INDEX($K$5:$K$104,MATCH(17,$N$5:$N$104,0)),"") | F21: =IFERROR(INDEX($L$5:$L$104,MATCH(17,$N$5:$N$104,0)),"") | H21: =IF(Allocation!B22="","",Allocation!B22) | I21: =IF(Allocation!C22="","",Allocation!C22) | J21: =IF(I21="","",SUMPRODUCT((Fixtures!D$5:D$76=I21)*(Fixtures!E$5:E$76<>"")*(Fixtures!F$5:F$76<>"")*((Fixtures!E$5:E$76>Fixtures!F$5:F$76)*3+(Fixtures!E$5:E$76=Fixtures!F$5:F$76)*2))+SUMPRODUCT((Fixtures!G$5:G$76=I21)*(Fixtures!E$5:E$76<>"")*(Fixtures!F$5:F$76<>"")*((Fixtures!F$5:F$76>Fixtures!E$5:E$76)*3+(Fixtures!E$5:E$76=Fixtures!F$5:F$76)*2))) | K21: =IF(I21="","",COUNTIFS(Fixtures!D$5:D$76,I21,Fixtures!J$5:J$76,"W")+COUNTIFS(Fixtures!G$5:G$76,I21,Fixtures!K$5:K$76,"W")) | L21: =IF(I21="","",COUNTIFS(Fixtures!D$5:D$76,I21,Fixtures!J$5:J$76,"D")+COUNTIFS(Fixtures!G$5:G$76,I21,Fixtures!K$5:K$76,"D")) | M21: =IF(I21="","",SUMPRODUCT((Fixtures!D$5:D$76=I21)*(Fixtures!E$5:E$76<>"")*(Fixtures!F$5:F$76<>"")*(Fixtures!E$5:E$76-Fixtures!F$5:F$76))+SUMPRODUCT((Fixtures!G$5:G$76=I21)*(Fixtures!E$5:E$76<>"")*(Fixtures!F$5:F$76<>"")*(Fixtures!F$5:F$76-Fixtures!E$5:E$76))) | N21: =IF(H21="","",COUNTIFS($J$5:$J$104,">"&J21,$H$5:$H$104,"<>")+COUNTIFS($J$5:$J21,J21,$H$5:$H21,"<>"))
A22: 18 | B22: =IFERROR(INDEX($H$5:$H$104,MATCH(18,$N$5:$N$104,0)),"") | C22: =IFERROR(INDEX($I$5:$I$104,MATCH(18,$N$5:$N$104,0)),"") | D22: =IFERROR(INDEX($J$5:$J$104,MATCH(18,$N$5:$N$104,0)),"") | E22: =IFERROR(INDEX($K$5:$K$104,MATCH(18,$N$5:$N$104,0)),"") | F22: =IFERROR(INDEX($L$5:$L$104,MATCH(18,$N$5:$N$104,0)),"") | H22: =IF(Allocation!B23="","",Allocation!B23) | I22: =IF(Allocation!C23="","",Allocation!C23) | J22: =IF(I22="","",SUMPRODUCT((Fixtures!D$5:D$76=I22)*(Fixtures!E$5:E$76<>"")*(Fixtures!F$5:F$76<>"")*((Fixtures!E$5:E$76>Fixtures!F$5:F$76)*3+(Fixtures!E$5:E$76=Fixtures!F$5:F$76)*2))+SUMPRODUCT((Fixtures!G$5:G$76=I22)*(Fixtures!E$5:E$76<>"")*(Fixtures!F$5:F$76<>"")*((Fixtures!F$5:F$76>Fixtures!E$5:E$76)*3+(Fixtures!E$5:E$76=Fixtures!F$5:F$76)*2))) | K22: =IF(I22="","",COUNTIFS(Fixtures!D$5:D$76,I22,Fixtures!J$5:J$76,"W")+COUNTIFS(Fixtures!G$5:G$76,I22,Fixtures!K$5:K$76,"W")) | L22: =IF(I22="","",COUNTIFS(Fixtures!D$5:D$76,I22,Fixtures!J$5:J$76,"D")+COUNTIFS(Fixtures!G$5:G$76,I22,Fixtures!K$5:K$76,"D")) | M22: =IF(I22="","",SUMPRODUCT((Fixtures!D$5:D$76=I22)*(Fixtures!E$5:E$76<>"")*(Fixtures!F$5:F$76<>"")*(Fixtures!E$5:E$76-Fixtures!F$5:F$76))+SUMPRODUCT((Fixtures!G$5:G$76=I22)*(Fixtures!E$5:E$76<>"")*(Fixtures!F$5:F$76<>"")*(Fixtures!F$5:F$76-Fixtures!E$5:E$76))) | N22: =IF(H22="","",COUNTIFS($J$5:$J$104,">"&J22,$H$5:$H$104,"<>")+COUNTIFS($J$5:$J22,J22,$H$5:$H22,"<>"))
A23: 19 | B23: =IFERROR(INDEX($H$5:$H$104,MATCH(19,$N$5:$N$104,0)),"") | C23: =IFERROR(INDEX($I$5:$I$104,MATCH(19,$N$5:$N$104,0)),"") | D23: =IFERROR(INDEX($J$5:$J$104,MATCH(19,$N$5:$N$104,0)),"") | E23: =IFERROR(INDEX($K$5:$K$104,MATCH(19,$N$5:$N$104,0)),"") | F23: =IFERROR(INDEX($L$5:$L$104,MATCH(19,$N$5:$N$104,0)),"") | H23: =IF(Allocation!B24="","",Allocation!B24) | I23: =IF(Allocation!C24="","",Allocation!C24) | J23: =IF(I23="","",SUMPRODUCT((Fixtures!D$5:D$76=I23)*(Fixtures!E$5:E$76<>"")*(Fixtures!F$5:F$76<>"")*((Fixtures!E$5:E$76>Fixtures!F$5:F$76)*3+(Fixtures!E$5:E$76=Fixtures!F$5:F$76)*2))+SUMPRODUCT((Fixtures!G$5:G$76=I23)*(Fixtures!E$5:E$76<>"")*(Fixtures!F$5:F$76<>"")*((Fixtures!F$5:F$76>Fixtures!E$5:E$76)*3+(Fixtures!E$5:E$76=Fixtures!F$5:F$76)*2))) | K23: =IF(I23="","",COUNTIFS(Fixtures!D$5:D$76,I23,Fixtures!J$5:J$76,"W")+COUNTIFS(Fixtures!G$5:G$76,I23,Fixtures!K$5:K$76,"W")) | L23: =IF(I23="","",COUNTIFS(Fixtures!D$5:D$76,I23,Fixtures!J$5:J$76,"D")+COUNTIFS(Fixtures!G$5:G$76,I23,Fixtures!K$5:K$76,"D")) | M23: =IF(I23="","",SUMPRODUCT((Fixtures!D$5:D$76=I23)*(Fixtures!E$5:E$76<>"")*(Fixtures!F$5:F$76<>"")*(Fixtures!E$5:E$76-Fixtures!F$5:F$76))+SUMPRODUCT((Fixtures!G$5:G$76=I23)*(Fixtures!E$5:E$76<>"")*(Fixtures!F$5:F$76<>"")*(Fixtures!F$5:F$76-Fixtures!E$5:E$76))) | N23: =IF(H23="","",COUNTIFS($J$5:$J$104,">"&J23,$H$5:$H$104,"<>")+COUNTIFS($J$5:$J23,J23,$H$5:$H23,"<>"))
A24: 20 | B24: =IFERROR(INDEX($H$5:$H$104,MATCH(20,$N$5:$N$104,0)),"") | C24: =IFERROR(INDEX($I$5:$I$104,MATCH(20,$N$5:$N$104,0)),"") | D24: =IFERROR(INDEX($J$5:$J$104,MATCH(20,$N$5:$N$104,0)),"") | E24: =IFERROR(INDEX($K$5:$K$104,MATCH(20,$N$5:$N$104,0)),"") | F24: =IFERROR(INDEX($L$5:$L$104,MATCH(20,$N$5:$N$104,0)),"") | H24: =IF(Allocation!B25="","",Allocation!B25) | I24: =IF(Allocation!C25="","",Allocation!C25) | J24: =IF(I24="","",SUMPRODUCT((Fixtures!D$5:D$76=I24)*(Fixtures!E$5:E$76<>"")*(Fixtures!F$5:F$76<>"")*((Fixtures!E$5:E$76>Fixtures!F$5:F$76)*3+(Fixtures!E$5:E$76=Fixtures!F$5:F$76)*2))+SUMPRODUCT((Fixtures!G$5:G$76=I24)*(Fixtures!E$5:E$76<>"")*(Fixtures!F$5:F$76<>"")*((Fixtures!F$5:F$76>Fixtures!E$5:E$76)*3+(Fixtures!E$5:E$76=Fixtures!F$5:F$76)*2))) | K24: =IF(I24="","",COUNTIFS(Fixtures!D$5:D$76,I24,Fixtures!J$5:J$76,"W")+COUNTIFS(Fixtures!G$5:G$76,I24,Fixtures!K$5:K$76,"W")) | L24: =IF(I24="","",COUNTIFS(Fixtures!D$5:D$76,I24,Fixtures!J$5:J$76,"D")+COUNTIFS(Fixtures!G$5:G$76,I24,Fixtures!K$5:K$76,"D")) | M24: =IF(I24="","",SUMPRODUCT((Fixtures!D$5:D$76=I24)*(Fixtures!E$5:E$76<>"")*(Fixtures!F$5:F$76<>"")*(Fixtures!E$5:E$76-Fixtures!F$5:F$76))+SUMPRODUCT((Fixtures!G$5:G$76=I24)*(Fixtures!E$5:E$76<>"")*(Fixtures!F$5:F$76<>"")*(Fixtures!F$5:F$76-Fixtures!E$5:E$76))) | N24: =IF(H24="","",COUNTIFS($J$5:$J$104,">"&J24,$H$5:$H$104,"<>")+COUNTIFS($J$5:$J24,J24,$H$5:$H24,"<>"))
A25: 21 | B25: =IFERROR(INDEX($H$5:$H$104,MATCH(21,$N$5:$N$104,0)),"") | C25: =IFERROR(INDEX($I$5:$I$104,MATCH(21,$N$5:$N$104,0)),"") | D25: =IFERROR(INDEX($J$5:$J$104,MATCH(21,$N$5:$N$104,0)),"") | E25: =IFERROR(INDEX($K$5:$K$104,MATCH(21,$N$5:$N$104,0)),"") | F25: =IFERROR(INDEX($L$5:$L$104,MATCH(21,$N$5:$N$104,0)),"") | H25: =IF(Allocation!B26="","",Allocation!B26) | I25: =IF(Allocation!C26="","",Allocation!C26) | J25: =IF(I25="","",SUMPRODUCT((Fixtures!D$5:D$76=I25)*(Fixtures!E$5:E$76<>"")*(Fixtures!F$5:F$76<>"")*((Fixtures!E$5:E$76>Fixtures!F$5:F$76)*3+(Fixtures!E$5:E$76=Fixtures!F$5:F$76)*2))+SUMPRODUCT((Fixtures!G$5:G$76=I25)*(Fixtures!E$5:E$76<>"")*(Fixtures!F$5:F$76<>"")*((Fixtures!F$5:F$76>Fixtures!E$5:E$76)*3+(Fixtures!E$5:E$76=Fixtures!F$5:F$76)*2))) | K25: =IF(I25="","",COUNTIFS(Fixtures!D$5:D$76,I25,Fixtures!J$5:J$76,"W")+COUNTIFS(Fixtures!G$5:G$76,I25,Fixtures!K$5:K$76,"W")) | L25: =IF(I25="","",COUNTIFS(Fixtures!D$5:D$76,I25,Fixtures!J$5:J$76,"D")+COUNTIFS(Fixtures!G$5:G$76,I25,Fixtures!K$5:K$76,"D")) | M25: =IF(I25="","",SUMPRODUCT((Fixtures!D$5:D$76=I25)*(Fixtures!E$5:E$76<>"")*(Fixtures!F$5:F$76<>"")*(Fixtures!E$5:E$76-Fixtures!F$5:F$76))+SUMPRODUCT((Fixtures!G$5:G$76=I25)*(Fixtures!E$5:E$76<>"")*(Fixtures!F$5:F$76<>"")*(Fixtures!F$5:F$76-Fixtures!E$5:E$76))) | N25: =IF(H25="","",COUNTIFS($J$5:$J$104,">"&J25,$H$5:$H$104,"<>")+COUNTIFS($J$5:$J25,J25,$H$5:$H25,"<>"))
A26: 22 | B26: =IFERROR(INDEX($H$5:$H$104,MATCH(22,$N$5:$N$104,0)),"") | C26: =IFERROR(INDEX($I$5:$I$104,MATCH(22,$N$5:$N$104,0)),"") | D26: =IFERROR(INDEX($J$5:$J$104,MATCH(22,$N$5:$N$104,0)),"") | E26: =IFERROR(INDEX($K$5:$K$104,MATCH(22,$N$5:$N$104,0)),"") | F26: =IFERROR(INDEX($L$5:$L$104,MATCH(22,$N$5:$N$104,0)),"") | H26: =IF(Allocation!B27="","",Allocation!B27) | I26: =IF(Allocation!C27="","",Allocation!C27) | J26: =IF(I26="","",SUMPRODUCT((Fixtures!D$5:D$76=I26)*(Fixtures!E$5:E$76<>"")*(Fixtures!F$5:F$76<>"")*((Fixtures!E$5:E$76>Fixtures!F$5:F$76)*3+(Fixtures!E$5:E$76=Fixtures!F$5:F$76)*2))+SUMPRODUCT((Fixtures!G$5:G$76=I26)*(Fixtures!E$5:E$76<>"")*(Fixtures!F$5:F$76<>"")*((Fixtures!F$5:F$76>Fixtures!E$5:E$76)*3+(Fixtures!E$5:E$76=Fixtures!F$5:F$76)*2))) | K26: =IF(I26="","",COUNTIFS(Fixtures!D$5:D$76,I26,Fixtures!J$5:J$76,"W")+COUNTIFS(Fixtures!G$5:G$76,I26,Fixtures!K$5:K$76,"W")) | L26: =IF(I26="","",COUNTIFS(Fixtures!D$5:D$76,I26,Fixtures!J$5:J$76,"D")+COUNTIFS(Fixtures!G$5:G$76,I26,Fixtures!K$5:K$76,"D")) | M26: =IF(I26="","",SUMPRODUCT((Fixtures!D$5:D$76=I26)*(Fixtures!E$5:E$76<>"")*(Fixtures!F$5:F$76<>"")*(Fixtures!E$5:E$76-Fixtures!F$5:F$76))+SUMPRODUCT((Fixtures!G$5:G$76=I26)*(Fixtures!E$5:E$76<>"")*(Fixtures!F$5:F$76<>"")*(Fixtures!F$5:F$76-Fixtures!E$5:E$76))) | N26: =IF(H26="","",COUNTIFS($J$5:$J$104,">"&J26,$H$5:$H$104,"<>")+COUNTIFS($J$5:$J26,J26,$H$5:$H26,"<>"))
A27: 23 | B27: =IFERROR(INDEX($H$5:$H$104,MATCH(23,$N$5:$N$104,0)),"") | C27: =IFERROR(INDEX($I$5:$I$104,MATCH(23,$N$5:$N$104,0)),"") | D27: =IFERROR(INDEX($J$5:$J$104,MATCH(23,$N$5:$N$104,0)),"") | E27: =IFERROR(INDEX($K$5:$K$104,MATCH(23,$N$5:$N$104,0)),"") | F27: =IFERROR(INDEX($L$5:$L$104,MATCH(23,$N$5:$N$104,0)),"") | H27: =IF(Allocation!B28="","",Allocation!B28) | I27: =IF(Allocation!C28="","",Allocation!C28) | J27: =IF(I27="","",SUMPRODUCT((Fixtures!D$5:D$76=I27)*(Fixtures!E$5:E$76<>"")*(Fixtures!F$5:F$76<>"")*((Fixtures!E$5:E$76>Fixtures!F$5:F$76)*3+(Fixtures!E$5:E$76=Fixtures!F$5:F$76)*2))+SUMPRODUCT((Fixtures!G$5:G$76=I27)*(Fixtures!E$5:E$76<>"")*(Fixtures!F$5:F$76<>"")*((Fixtures!F$5:F$76>Fixtures!E$5:E$76)*3+(Fixtures!E$5:E$76=Fixtures!F$5:F$76)*2))) | K27: =IF(I27="","",COUNTIFS(Fixtures!D$5:D$76,I27,Fixtures!J$5:J$76,"W")+COUNTIFS(Fixtures!G$5:G$76,I27,Fixtures!K$5:K$76,"W")) | L27: =IF(I27="","",COUNTIFS(Fixtures!D$5:D$76,I27,Fixtures!J$5:J$76,"D")+COUNTIFS(Fixtures!G$5:G$76,I27,Fixtures!K$5:K$76,"D")) | M27: =IF(I27="","",SUMPRODUCT((Fixtures!D$5:D$76=I27)*(Fixtures!E$5:E$76<>"")*(Fixtures!F$5:F$76<>"")*(Fixtures!E$5:E$76-Fixtures!F$5:F$76))+SUMPRODUCT((Fixtures!G$5:G$76=I27)*(Fixtures!E$5:E$76<>"")*(Fixtures!F$5:F$76<>"")*(Fixtures!F$5:F$76-Fixtures!E$5:E$76))) | N27: =IF(H27="","",COUNTIFS($J$5:$J$104,">"&J27,$H$5:$H$104,"<>")+COUNTIFS($J$5:$J27,J27,$H$5:$H27,"<>"))
A28: 24 | B28: =IFERROR(INDEX($H$5:$H$104,MATCH(24,$N$5:$N$104,0)),"") | C28: =IFERROR(INDEX($I$5:$I$104,MATCH(24,$N$5:$N$104,0)),"") | D28: =IFERROR(INDEX($J$5:$J$104,MATCH(24,$N$5:$N$104,0)),"") | E28: =IFERROR(INDEX($K$5:$K$104,MATCH(24,$N$5:$N$104,0)),"") | F28: =IFERROR(INDEX($L$5:$L$104,MATCH(24,$N$5:$N$104,0)),"") | H28: =IF(Allocation!B29="","",Allocation!B29) | I28: =IF(Allocation!C29="","",Allocation!C29) | J28: =IF(I28="","",SUMPRODUCT((Fixtures!D$5:D$76=I28)*(Fixtures!E$5:E$76<>"")*(Fixtures!F$5:F$76<>"")*((Fixtures!E$5:E$76>Fixtures!F$5:F$76)*3+(Fixtures!E$5:E$76=Fixtures!F$5:F$76)*2))+SUMPRODUCT((Fixtures!G$5:G$76=I28)*(Fixtures!E$5:E$76<>"")*(Fixtures!F$5:F$76<>"")*((Fixtures!F$5:F$76>Fixtures!E$5:E$76)*3+(Fixtures!E$5:E$76=Fixtures!F$5:F$76)*2))) | K28: =IF(I28="","",COUNTIFS(Fixtures!D$5:D$76,I28,Fixtures!J$5:J$76,"W")+COUNTIFS(Fixtures!G$5:G$76,I28,Fixtures!K$5:K$76,"W")) | L28: =IF(I28="","",COUNTIFS(Fixtures!D$5:D$76,I28,Fixtures!J$5:J$76,"D")+COUNTIFS(Fixtures!G$5:G$76,I28,Fixtures!K$5:K$76,"D")) | M28: =IF(I28="","",SUMPRODUCT((Fixtures!D$5:D$76=I28)*(Fixtures!E$5:E$76<>"")*(Fixtures!F$5:F$76<>"")*(Fixtures!E$5:E$76-Fixtures!F$5:F$76))+SUMPRODUCT((Fixtures!G$5:G$76=I28)*(Fixtures!E$5:E$76<>"")*(Fixtures!F$5:F$76<>"")*(Fixtures!F$5:F$76-Fixtures!E$5:E$76))) | N28: =IF(H28="","",COUNTIFS($J$5:$J$104,">"&J28,$H$5:$H$104,"<>")+COUNTIFS($J$5:$J28,J28,$H$5:$H28,"<>"))
A29: 25 | B29: =IFERROR(INDEX($H$5:$H$104,MATCH(25,$N$5:$N$104,0)),"") | C29: =IFERROR(INDEX($I$5:$I$104,MATCH(25,$N$5:$N$104,0)),"") | D29: =IFERROR(INDEX($J$5:$J$104,MATCH(25,$N$5:$N$104,0)),"") | E29: =IFERROR(INDEX($K$5:$K$104,MATCH(25,$N$5:$N$104,0)),"") | F29: =IFERROR(INDEX($L$5:$L$104,MATCH(25,$N$5:$N$104,0)),"") | H29: =IF(Allocation!B30="","",Allocation!B30) | I29: =IF(Allocation!C30="","",Allocation!C30) | J29: =IF(I29="","",SUMPRODUCT((Fixtures!D$5:D$76=I29)*(Fixtures!E$5:E$76<>"")*(Fixtures!F$5:F$76<>"")*((Fixtures!E$5:E$76>Fixtures!F$5:F$76)*3+(Fixtures!E$5:E$76=Fixtures!F$5:F$76)*2))+SUMPRODUCT((Fixtures!G$5:G$76=I29)*(Fixtures!E$5:E$76<>"")*(Fixtures!F$5:F$76<>"")*((Fixtures!F$5:F$76>Fixtures!E$5:E$76)*3+(Fixtures!E$5:E$76=Fixtures!F$5:F$76)*2))) | K29: =IF(I29="","",COUNTIFS(Fixtures!D$5:D$76,I29,Fixtures!J$5:J$76,"W")+COUNTIFS(Fixtures!G$5:G$76,I29,Fixtures!K$5:K$76,"W")) | L29: =IF(I29="","",COUNTIFS(Fixtures!D$5:D$76,I29,Fixtures!J$5:J$76,"D")+COUNTIFS(Fixtures!G$5:G$76,I29,Fixtures!K$5:K$76,"D")) | M29: =IF(I29="","",SUMPRODUCT((Fixtures!D$5:D$76=I29)*(Fixtures!E$5:E$76<>"")*(Fixtures!F$5:F$76<>"")*(Fixtures!E$5:E$76-Fixtures!F$5:F$76))+SUMPRODUCT((Fixtures!G$5:G$76=I29)*(Fixtures!E$5:E$76<>"")*(Fixtures!F$5:F$76<>"")*(Fixtures!F$5:F$76-Fixtures!E$5:E$76))) | N29: =IF(H29="","",COUNTIFS($J$5:$J$104,">"&J29,$H$5:$H$104,"<>")+COUNTIFS($J$5:$J29,J29,$H$5:$H29,"<>"))
A30: 26 | B30: =IFERROR(INDEX($H$5:$H$104,MATCH(26,$N$5:$N$104,0)),"") | C30: =IFERROR(INDEX($I$5:$I$104,MATCH(26,$N$5:$N$104,0)),"") | D30: =IFERROR(INDEX($J$5:$J$104,MATCH(26,$N$5:$N$104,0)),"") | E30: =IFERROR(INDEX($K$5:$K$104,MATCH(26,$N$5:$N$104,0)),"") | F30: =IFERROR(INDEX($L$5:$L$104,MATCH(26,$N$5:$N$104,0)),"") | H30: =IF(Allocation!B31="","",Allocation!B31) | I30: =IF(Allocation!C31="","",Allocation!C31) | J30: =IF(I30="","",SUMPRODUCT((Fixtures!D$5:D$76=I30)*(Fixtures!E$5:E$76<>"")*(Fixtures!F$5:F$76<>"")*((Fixtures!E$5:E$76>Fixtures!F$5:F$76)*3+(Fixtures!E$5:E$76=Fixtures!F$5:F$76)*2))+SUMPRODUCT((Fixtures!G$5:G$76=I30)*(Fixtures!E$5:E$76<>"")*(Fixtures!F$5:F$76<>"")*((Fixtures!F$5:F$76>Fixtures!E$5:E$76)*3+(Fixtures!E$5:E$76=Fixtures!F$5:F$76)*2))) | K30: =IF(I30="","",COUNTIFS(Fixtures!D$5:D$76,I30,Fixtures!J$5:J$76,"W")+COUNTIFS(Fixtures!G$5:G$76,I30,Fixtures!K$5:K$76,"W")) | L30: =IF(I30="","",COUNTIFS(Fixtures!D$5:D$76,I30,Fixtures!J$5:J$76,"D")+COUNTIFS(Fixtures!G$5:G$76,I30,Fixtures!K$5:K$76,"D")) | M30: =IF(I30="","",SUMPRODUCT((Fixtures!D$5:D$76=I30)*(Fixtures!E$5:E$76<>"")*(Fixtures!F$5:F$76<>"")*(Fixtures!E$5:E$76-Fixtures!F$5:F$76))+SUMPRODUCT((Fixtures!G$5:G$76=I30)*(Fixtures!E$5:E$76<>"")*(Fixtures!F$5:F$76<>"")*(Fixtures!F$5:F$76-Fixtures!E$5:E$76))) | N30: =IF(H30="","",COUNTIFS($J$5:$J$104,">"&J30,$H$5:$H$104,"<>")+COUNTIFS($J$5:$J30,J30,$H$5:$H30,"<>"))
